Workbook

Sheet Start Here
B1: ✨ WEDDING PLANNER — VERSION 2.0
B2: Wedding Planner Spreadsheet • Novality Store • Version 2.0
B3: ✏️ Cream cells = your input 🔒 Grey cells = protected formulas • Novality Store Version 2.0
B5: ABOUT THIS WORKBOOK
B6: Workbook | C6: Wedding Planner Spreadsheet — Version 2.0
B7: Author | C7: Novality Store
B8: Tabs | C8: 52 beautifully linked planning sheets
B9: Protection | C9: Every formula cell is locked — sheets are password-protected
B11: HOW IT WORKS
B12: 1. Start on the Dashboard — set your wedding date and every countdown updates itself.
B13: 2. Fill in the cream cells. Grey cells are formulas — they calculate automatically and are locked.
B14: 3. Each sheet is protected so formulas can't be deleted by accident (Review ▸ Unprotect Sheet to customize).
B15: 4. The Guest List feeds the Invitations Tracker, Meal Counts, Seating Chart and Thank-You Cards.
B16: 5. The Master Budget feeds the Dashboard, Budget Breakdown chart and Contributions tracker.
B18: WHAT'S INSIDE — TAP ANY TAB NAME TO JUMP THERE
B19: BIG PICTURE PLANNING
B20: ▸ Dashboard | C20: Wedding overview — date, venue, theme, budget & live counters
B21: ▸ Countdown Checklist | C21: 12-month, 6-month, 3-month, 1-month, 1-week & day-of tasks
B22: ▸ Vision Board | C22: Mood, style keywords and inspiration sources
B23: ▸ Priority Ranking | C23: Rank the 3–5 things that matter most
B24: BUDGET & FINANCE
B25: ▸ Master Budget | C25: Estimated vs actual, deposits paid & balance due per category
B26: ▸ Payment Tracker | C26: Every vendor payment — due dates, amounts & status
B27: ▸ Budget Breakdown | C27: Category totals, % of budget and a live pie chart
B28: ▸ Contributions | C28: Cash fund & who is contributing what
B29: GUEST MANAGEMENT
B30: ▸ Guest List | C30: Master list — RSVP, meal choice, +1 and table number
B31: ▸ Invitations Tracker | C31: Save-the-dates, invitations and RSVP replies
B32: ▸ Seating Chart | C32: Assign confirmed guests to reception tables
B33: ▸ Hotel & Welcome Bags | C33: Out-of-town guests, room blocks & welcome bags
B34: ▸ Meal Count Summary | C34: Caterer-ready meal & dietary counts (auto-calculated)
B35: VENDOR MANAGEMENT
B36: ▸ Vendor Contacts | C36: All 11 vendor categories — contacts, contracts & balances
B37: ▸ Vendor Comparison | C37: Side-by-side comparison of 2–3 options per category
B38: ATTIRE & BEAUTY
B39: ▸ Dress Shopping Log | C39: Stores, styles, prices & alterations timeline
B40: ▸ Bridesmaid Dresses | C40: Sizes, colors, orders & delivery status
B41: ▸ Groom & Groomsmen | C41: Suit/tux details, rental vs purchase & fittings
B42: ▸ Hair & Makeup Trials | C42: Artists, looks, products & trial notes
B43: ▸ Beauty Timeline | C43: Skincare, whitening, tanning & nails schedule
...

Sheet Dashboard
B1: 💒 WEDDING OVERVIEW DASHBOARD
B2: Your big picture at a glance • updates automatically
B3: ✏️ Cream cells = your input 🔒 Grey cells = protected formulas • Novality Store Version 2.0
B5: THE COUPLE & THE DAY
B6: Partner 1 | C6: Alex Morgan
B7: Partner 2 | C7: Jordan Lee
B8: Wedding Date | C8: 46529 | E8: =IF($C$8="","—",$C$8-TODAY())
B9: Ceremony Time | C9: 4:00 PM
B10: Venue | C10: The Rosewood Estate
B11: City / Location | C11: Asheville, North Carolina
B12: Theme / Style | C12: Romantic garden party
B13: Hashtag (auto) | C13: =IF(OR($C$6="",$C$7=""),"","#"&SUBSTITUTE(LOWER($C$6&$C$7)," ",""))
B15: COLOR PALETTE
B16: Swatches
B17: Color name | C17: Blush | D17: Rose | E17: Rose Gold | F17: Sage | G17: Gold | H17: Ivory
B18: Where it's used
B20: BUDGET AT A GLANCE
B21: Total estimated | C21: ='Master Budget'!$C$31 | E21: =IF(N($C$21)=0,"",N($C21)/$C$21)
B22: Actual / committed | C22: ='Master Budget'!$D$31 | E22: =IF(N($C$21)=0,"",N($C22)/$C$21)
B23: Deposits paid | C23: ='Master Budget'!$E$31 | E23: =IF(N($C$21)=0,"",N($C23)/$C$21)
B24: Balance remaining | C24: ='Master Budget'!$F$31 | E24: =IF(N($C$21)=0,"",N($C24)/$C$21)
B25: Budget used | C25: =IF(N('Master Budget'!$C$31)=0,"",N('Master Budget'!$D$31)/'Master Budget'!$C$31)
B27: GUEST SNAPSHOT
B28: Guests invited | C28: ='Guest List'!$C$5
B29: Confirmed | C29: ='Guest List'!$E$5
B30: Declined | C30: ='Guest List'!$G$5
B31: Awaiting reply | C31: ='Guest List'!$I$5
B32: Guests with a +1 | C32: ='Guest List'!$C$6
B34: ACTIONS & COUNTDOWNS
B35: Payments due in 30 days | C35: =COUNTIFS('Payment Tracker'!$E$9:$E$158,">="&TODAY(),'Payment Tracker'!$E$9:$E$158,"<="&TODAY()+30,'Payment Tracker'!$H$9:$H$158,"<>Paid")
B36: Next unpaid due date | C36: =IFERROR(IF(MINIFS('Payment Tracker'!$E$9:$E$158,'Payment Tracker'!$H$9:$H$158,"<>Paid",'Payment Tracker'!$E$9:$E$158,">="&TODAY())=0,"All caught up!",MINIFS('Payment Tracker'!$E$9:$E$158,'Payment Tracker'!$H$9:$H$158,"<>Paid",'Payment Tracker'!$E$9:$E$158,">="&TODAY())),"—")
B37: Checklist complete | C37: ='Countdown Checklist'!$E$5
B38: Vendors booked | C38: ='Vendor Contacts'!$E$5&" of "&'Vendor Contacts'!$C$5
B39: Thank-you cards sent | C39: ='Thank You Cards'!$C$5
B40: Honeymoon budget | C40: ='Honeymoon Planner'!$C$17
B42: 🔒 Everything on this page is calculated automatically from your other tabs.

Sheet Countdown Checklist
B1: ⏳ COUNTDOWN CHECKLIST
B2: 12-month → 6-month → 3-month → 1-month → 1-week → day-of
B3: ✏️ Cream cells = your input 🔒 Grey cells = protected formulas • Novality Store Version 2.0
B5: TASKS DONE | C5: =COUNTIF($E$9:$E$120,"Done") | D5: % COMPLETE | E5: =IF(COUNTA($C$9:$C$120)=0,"",COUNTIF($E$9:$E$120,"Done")/COUNTA($C$9:$C$120))
B8: Phase | C8: Task | D8: Target Date (auto) | E8: Status | F8: Notes
B9: 12 Months Before | C9: Set the wedding date & book the officiant | D9: =IF($B9="","",IF(Dashboard!$C$8="","",IF($B9="Day-Of",Dashboard!$C$8,IF($B9="1 Week Before",Dashboard!$C$8-7,IF($B9="1 Month Before",EDATE(Dashboard!$C$8,-1),IF($B9="3 Months Before",EDATE(Dashboard!$C$8,-3),IF($B9="6 Months Before",EDATE(Dashboard!$C$8,-6),IF($B9="12 Months Before",EDATE(Dashboard!$C$8,-12),""))))))))
B10: 12 Months Before | C10: Draft the budget & open a wedding savings account | D10: =IF($B10="","",IF(Dashboard!$C$8="","",IF($B10="Day-Of",Dashboard!$C$8,IF($B10="1 Week Before",Dashboard!$C$8-7,IF($B10="1 Month Before",EDATE(Dashboard!$C$8,-1),IF($B10="3 Months Before",EDATE(Dashboard!$C$8,-3),IF($B10="6 Months Before",EDATE(Dashboard!$C$8,-6),IF($B10="12 Months Before",EDATE(Dashboard!$C$8,-12),""))))))))
B11: 12 Months Before | C11: Start the master guest list (use the Guest List tab) | D11: =IF($B11="","",IF(Dashboard!$C$8="","",IF($B11="Day-Of",Dashboard!$C$8,IF($B11="1 Week Before",Dashboard!$C$8-7,IF($B11="1 Month Before",EDATE(Dashboard!$C$8,-1),IF($B11="3 Months Before",EDATE(Dashboard!$C$8,-3),IF($B11="6 Months Before",EDATE(Dashboard!$C$8,-6),IF($B11="12 Months Before",EDATE(Dashboard!$C$8,-12),""))))))))
B12: 12 Months Before | C12: Hire a wedding planner / coordinator | D12: =IF($B12="","",IF(Dashboard!$C$8="","",IF($B12="Day-Of",Dashboard!$C$8,IF($B12="1 Week Before",Dashboard!$C$8-7,IF($B12="1 Month Before",EDATE(Dashboard!$C$8,-1),IF($B12="3 Months Before",EDATE(Dashboard!$C$8,-3),IF($B12="6 Months Before",EDATE(Dashboard!$C$8,-6),IF($B12="12 Months Before",EDATE(Dashboard!$C$8,-12),""))))))))
B13: 12 Months Before | C13: Tour venues & book your favourite | D13: =IF($B13="","",IF(Dashboard!$C$8="","",IF($B13="Day-Of",Dashboard!$C$8,IF($B13="1 Week Before",Dashboard!$C$8-7,IF($B13="1 Month Before",EDATE(Dashboard!$C$8,-1),IF($B13="3 Months Before",EDATE(Dashboard!$C$8,-3),IF($B13="6 Months Before",EDATE(Dashboard!$C$8,-6),IF($B13="12 Months Before",EDATE(Dashboard!$C$8,-12),""))))))))
B14: 12 Months Before | C14: Choose your wedding party | D14: =IF($B14="","",IF(Dashboard!$C$8="","",IF($B14="Day-Of",Dashboard!$C$8,IF($B14="1 Week Before",Dashboard!$C$8-7,IF($B14="1 Month Before",EDATE(Dashboard!$C$8,-1),IF($B14="3 Months Before",EDATE(Dashboard!$C$8,-3),IF($B14="6 Months Before",EDATE(Dashboard!$C$8,-6),IF($B14="12 Months Before",EDATE(Dashboard!$C$8,-12),""))))))))
B15: 6 Months Before | C15: Book the caterer & schedule a tasting | D15: =IF($B15="","",IF(Dashboard!$C$8="","",IF($B15="Day-Of",Dashboard!$C$8,IF($B15="1 Week Before",Dashboard!$C$8-7,IF($B15="1 Month Before",EDATE(Dashboard!$C$8,-1),IF($B15="3 Months Before",EDATE(Dashboard!$C$8,-3),IF($B15="6 Months Before",EDATE(Dashboard!$C$8,-6),IF($B15="12 Months Before",EDATE(Dashboard!$C$8,-12),""))))))))
B16: 6 Months Before | C16: Book photographer & videographer | D16: =IF($B16="","",IF(Dashboard!$C$8="","",IF($B16="Day-Of",Dashboard!$C$8,IF($B16="1 Week Before",Dashboard!$C$8-7,IF($B16="1 Month Before",EDATE(Dashboard!$C$8,-1),IF($B16="3 Months Before",EDATE(Dashboard!$C$8,-3),IF($B16="6 Months Before",EDATE(Dashboard!$C$8,-6),IF($B16="12 Months Before",EDATE(Dashboard!$C$8,-12),""))))))))
B17: 6 Months Before | C17: Book DJ / band & extra entertainment | D17: =IF($B17="","",IF(Dashboard!$C$8="","",IF($B17="Day-Of",Dashboard!$C$8,IF($B17="1 Week Before",Dashboard!$C$8-7,IF($B17="1 Month Before",EDATE(Dashboard!$C$8,-1),IF($B17="3 Months Before",EDATE(Dashboard!$C$8,-3),IF($B17="6 Months Before",EDATE(Dashboard!$C$8,-6),IF($B17="12 Months Before",EDATE(Dashboard!$C$8,-12),""))))))))
B18: 6 Months Before | C18: Order the wedding gown (allow alterations time) | D18: =IF($B18="","",IF(Dashboard!$C$8="","",IF($B18="Day-Of",Dashboard!$C$8,IF($B18="1 Week Before",Dashboard!$C$8-7,IF($B18="1 Month Before",EDATE(Dashboard!$C$8,-1),IF($B18="3 Months Before",EDATE(Dashboard!$C$8,-3),IF($B18="6 Months Before",EDATE(Dashboard!$C$8,-6),IF($B18="12 Months Before",EDATE(Dashboard!$C$8,-12),""))))))))
B19: 6 Months Before | C19: Send save-the-dates | D19: =IF($B19="","",IF(Dashboard!$C$8="","",IF($B19="Day-Of",Dashboard!$C$8,IF($B19="1 Week Before",Dashboard!$C$8-7,IF($B19="1 Month Before",EDATE(Dashboard!$C$8,-1),IF($B19="3 Months Before",EDATE(Dashboard!$C$8,-3),IF($B19="6 Months Before",EDATE(Dashboard!$C$8,-6),IF($B19="12 Months Before",EDATE(Dashboard!$C$8,-12),""))))))))
B20: 6 Months Before | C20: Book the florist & lock the décor vision | D20: =IF($B20="","",IF(Dashboard!$C$8="","",IF($B20="Day-Of",Dashboard!$C$8,IF($B20="1 Week Before",Dashboard!$C$8-7,IF($B20="1 Month Before",EDATE(Dashboard!$C$8,-1),IF($B20="3 Months Before",EDATE(Dashboard!$C$8,-3),IF($B20="6 Months Before",EDATE(Dashboard!$C$8,-6),IF($B20="12 Months Before",EDATE(Dashboard!$C$8,-12),""))))))))
... B52: Day-Of | C52: Send-off & collect keepsakes | D52: =IF($B52="","",IF(Dashboard!$C$8="","",IF($B52="Day-Of",Dashboard!$C$8,IF($B52="1 Week Before",Dashboard!$C$8-7,IF($B52="1 Month Before",EDATE(Dashboard!$C$8,-1),IF($B52="3 Months Before",EDATE(Dashboard!$C$8,-3),IF($B52="6 Months Before",EDATE(Dashboard!$C$8,-6),IF($B52="12 Months Before",EDATE(Dashboard!$C$8,-12),""))))))))
D53: =IF($B53="","",IF(Dashboard!$C$8="","",IF($B53="Day-Of",Dashboard!$C$8,IF($B53="1 Week Before",Dashboard!$C$8-7,IF($B53="1 Month Before",EDATE(Dashboard!$C$8,-1),IF($B53="3 Months Before",EDATE(Dashboard!$C$8,-3),IF($B53="6 Months Before",EDATE(Dashboard!$C$8,-6),IF($B53="12 Months Before",EDATE(Dashboard!$C$8,-12),""))))))))
D54: =IF($B54="","",IF(Dashboard!$C$8="","",IF($B54="Day-Of",Dashboard!$C$8,IF($B54="1 Week Before",Dashboard!$C$8-7,IF($B54="1 Month Before",EDATE(Dashboard!$C$8,-1),IF($B54="3 Months Before",EDATE(Dashboard!$C$8,-3),IF($B54="6 Months Before",EDATE(Dashboard!$C$8,-6),IF($B54="12 Months Before",EDATE(Dashboard!$C$8,-12),""))))))))
D55: =IF($B55="","",IF(Dashboard!$C$8="","",IF($B55="Day-Of",Dashboard!$C$8,IF($B55="1 Week Before",Dashboard!$C$8-7,IF($B55="1 Month Before",EDATE(Dashboard!$C$8,-1),IF($B55="3 Months Before",EDATE(Dashboard!$C$8,-3),IF($B55="6 Months Before",EDATE(Dashboard!$C$8,-6),IF($B55="12 Months Before",EDATE(Dashboard!$C$8,-12),""))))))))
D56: =IF($B56="","",IF(Dashboard!$C$8="","",IF($B56="Day-Of",Dashboard!$C$8,IF($B56="1 Week Before",Dashboard!$C$8-7,IF($B56="1 Month Before",EDATE(Dashboard!$C$8,-1),IF($B56="3 Months Before",EDATE(Dashboard!$C$8,-3),IF($B56="6 Months Before",EDATE(Dashboard!$C$8,-6),IF($B56="12 Months Before",EDATE(Dashboard!$C$8,-12),""))))))))
D57: =IF($B57="","",IF(Dashboard!$C$8="","",IF($B57="Day-Of",Dashboard!$C$8,IF($B57="1 Week Before",Dashboard!$C$8-7,IF($B57="1 Month Before",EDATE(Dashboard!$C$8,-1),IF($B57="3 Months Before",EDATE(Dashboard!$C$8,-3),IF($B57="6 Months Before",EDATE(Dashboard!$C$8,-6),IF($B57="12 Months Before",EDATE(Dashboard!$C$8,-12),""))))))))
D58: =IF($B58="","",IF(Dashboard!$C$8="","",IF($B58="Day-Of",Dashboard!$C$8,IF($B58="1 Week Before",Dashboard!$C$8-7,IF($B58="1 Month Before",EDATE(Dashboard!$C$8,-1),IF($B58="3 Months Before",EDATE(Dashboard!$C$8,-3),IF($B58="6 Months Before",EDATE(Dashboard!$C$8,-6),IF($B58="12 Months Before",EDATE(Dashboard!$C$8,-12),""))))))))
D59: =IF($B59="","",IF(Dashboard!$C$8="","",IF($B59="Day-Of",Dashboard!$C$8,IF($B59="1 Week Before",Dashboard!$C$8-7,IF($B59="1 Month Before",EDATE(Dashboard!$C$8,-1),IF($B59="3 Months Before",EDATE(Dashboard!$C$8,-3),IF($B59="6 Months Before",EDATE(Dashboard!$C$8,-6),IF($B59="12 Months Before",EDATE(Dashboard!$C$8,-12),""))))))))
D60: =IF($B60="","",IF(Dashboard!$C$8="","",IF($B60="Day-Of",Dashboard!$C$8,IF($B60="1 Week Before",Dashboard!$C$8-7,IF($B60="1 Month Before",EDATE(Dashboard!$C$8,-1),IF($B60="3 Months Before",EDATE(Dashboard!$C$8,-3),IF($B60="6 Months Before",EDATE(Dashboard!$C$8,-6),IF($B60="12 Months Before",EDATE(Dashboard!$C$8,-12),""))))))))
D61: =IF($B61="","",IF(Dashboard!$C$8="","",IF($B61="Day-Of",Dashboard!$C$8,IF($B61="1 Week Before",Dashboard!$C$8-7,IF($B61="1 Month Before",EDATE(Dashboard!$C$8,-1),IF($B61="3 Months Before",EDATE(Dashboard!$C$8,-3),IF($B61="6 Months Before",EDATE(Dashboard!$C$8,-6),IF($B61="12 Months Before",EDATE(Dashboard!$C$8,-12),""))))))))
D62: =IF($B62="","",IF(Dashboard!$C$8="","",IF($B62="Day-Of",Dashboard!$C$8,IF($B62="1 Week Before",Dashboard!$C$8-7,IF($B62="1 Month Before",EDATE(Dashboard!$C$8,-1),IF($B62="3 Months Before",EDATE(Dashboard!$C$8,-3),IF($B62="6 Months Before",EDATE(Dashboard!$C$8,-6),IF($B62="12 Months Before",EDATE(Dashboard!$C$8,-12),""))))))))
D63: =IF($B63="","",IF(Dashboard!$C$8="","",IF($B63="Day-Of",Dashboard!$C$8,IF($B63="1 Week Before",Dashboard!$C$8-7,IF($B63="1 Month Before",EDATE(Dashboard!$C$8,-1),IF($B63="3 Months Before",EDATE(Dashboard!$C$8,-3),IF($B63="6 Months Before",EDATE(Dashboard!$C$8,-6),IF($B63="12 Months Before",EDATE(Dashboard!$C$8,-12),""))))))))
D64: =IF($B64="","",IF(Dashboard!$C$8="","",IF($B64="Day-Of",Dashboard!$C$8,IF($B64="1 Week Before",Dashboard!$C$8-7,IF($B64="1 Month Before",EDATE(Dashboard!$C$8,-1),IF($B64="3 Months Before",EDATE(Dashboard!$C$8,-3),IF($B64="6 Months Before",EDATE(Dashboard!$C$8,-6),IF($B64="12 Months Before",EDATE(Dashboard!$C$8,-12),""))))))))
... D77: =IF($B77="","",IF(Dashboard!$C$8="","",IF($B77="Day-Of",Dashboard!$C$8,IF($B77="1 Week Before",Dashboard!$C$8-7,IF($B77="1 Month Before",EDATE(Dashboard!$C$8,-1),IF($B77="3 Months Before",EDATE(Dashboard!$C$8,-3),IF($B77="6 Months Before",EDATE(Dashboard!$C$8,-6),IF($B77="12 Months Before",EDATE(Dashboard!$C$8,-12),""))))))))

Sheet Vision Board
B1: 🎨 WEDDING VISION BOARD
B2: Mood, style & inspiration
B3: ✏️ Cream cells = your input 🔒 Grey cells = protected formulas • Novality Store Version 2.0
B5: MOOD & FEELING
B6: Mood word | C6: How it shows up
B7: Romantic | C7: Soft light, candles, flowing fabric
B8: Whimsical | C8: Wildflowers, hand-lettered signs
B9: Warm | C9: Candlelight, wood tones, amber glow
B10: Intimate | C10: Long tables, acoustic music
B11: Joyful | C11: Bright florals, upbeat band set
B16: STYLE KEYWORDS
B17: Mood word | C17: How it shows up
B18: Garden party | C18: Stationery, floral arch
B19: Heirloom / vintage | C19: Rings, tableware, lace
B20: Candlelit | C20: Reception lighting
B21: Soft & natural | C21: Photography edit, linens
B26: INSPIRATION SOURCES
B27: Platform / source | C27: Link / handle | D27: What we love
B28: Pinterest | C28: pinterest.com/ourwedding | D28: Colour palettes & arches
B29: Instagram | C29: @greenhouse.florals | D29: Organic installation styles
B30: Magazine | C30: Brides — spring issue | D30: Stationery suite ideas
B36: THINGS WE LOVE vs THINGS TO AVOID
B37: We love 💕 | D37: We'd rather skip 🙅
B38: Unplugged ceremony Live acoustic cocktail hour Late-night snack surprise | D38: Dove releases Long gap between ceremony & dinner Chicken-dance playlist defaults

Sheet Priority Ranking
B1: 🥇 PRIORITY RANKING
B2: Agree on your top 3–5 before you spend a dollar
B3: ✏️ Cream cells = your input 🔒 Grey cells = protected formulas • Novality Store Version 2.0
B8: Rank | C8: What matters most | D8: Why it matters | E8: Budget share | F8: Notes
B9: 1 | C9: Photography & video | D9: The one thing we keep forever
B10: 2 | C10: Venue | D10: Sets the entire atmosphere of the day
B11: 3 | C11: Food & drink | D11: Guest experience is our love language
B12: 4 | C12: Music & entertainment | D12: A full dance floor all night
B13: 5 | C13: Guest comfort | D13: Shuttles, welcome bags, no-long-gaps
B19: TOTAL | E19: =SUM(E9:E18)
B21: 💡 Tip: aim for your top 3 priorities to take roughly 60–70% of the budget — and let the rest be 'good enough'.

Sheet Master Budget
B1: 💰 MASTER BUDGET
B2: Estimated vs actual — deposits & balance due (balance auto-calculates)
B3: ✏️ Cream cells = your input 🔒 Grey cells = protected formulas • Novality Store Version 2.0
B8: Category | C8: Estimated cost | D8: Actual cost | E8: Deposit paid | F8: Balance due 🔒 | G8: % of est. 🔒 | H8: Vendor | I8: Notes
B9: Venue & rental | C9: 8500 | D9: 8000 | E9: 2000 | F9: =IF(AND($B9="",$C9="",$D9="",$E9=""),"",MAX(0,N(IF($D9="",$C9,$D9))-N($E9))) | G9: =IF(OR($C9="",N($C$31)=0),"",N($C9)/$C$31)
B10: Catering & bar | C10: 12000 | D10: 11500 | E10: 3000 | F10: =IF(AND($B10="",$C10="",$D10="",$E10=""),"",MAX(0,N(IF($D10="",$C10,$D10))-N($E10))) | G10: =IF(OR($C10="",N($C$31)=0),"",N($C10)/$C$31)
B11: Wedding cake | C11: 650 | D11: 650 | E11: 200 | F11: =IF(AND($B11="",$C11="",$D11="",$E11=""),"",MAX(0,N(IF($D11="",$C11,$D11))-N($E11))) | G11: =IF(OR($C11="",N($C$31)=0),"",N($C11)/$C$31)
B12: Bridal attire | C12: 1800 | D12: 1750 | E12: 600 | F12: =IF(AND($B12="",$C12="",$D12="",$E12=""),"",MAX(0,N(IF($D12="",$C12,$D12))-N($E12))) | G12: =IF(OR($C12="",N($C$31)=0),"",N($C12)/$C$31)
B13: Groom & party attire | C13: 950 | D13: 900 | E13: 300 | F13: =IF(AND($B13="",$C13="",$D13="",$E13=""),"",MAX(0,N(IF($D13="",$C13,$D13))-N($E13))) | G13: =IF(OR($C13="",N($C$31)=0),"",N($C13)/$C$31)
B14: Hair & makeup | C14: 600 | D14: 550 | E14: 150 | F14: =IF(AND($B14="",$C14="",$D14="",$E14=""),"",MAX(0,N(IF($D14="",$C14,$D14))-N($E14))) | G14: =IF(OR($C14="",N($C$31)=0),"",N($C14)/$C$31)
B15: Flowers & décor | C15: 2800 | E15: 700 | F15: =IF(AND($B15="",$C15="",$D15="",$E15=""),"",MAX(0,N(IF($D15="",$C15,$D15))-N($E15))) | G15: =IF(OR($C15="",N($C$31)=0),"",N($C15)/$C$31)
B16: Photography | C16: 3200 | E16: 800 | F16: =IF(AND($B16="",$C16="",$D16="",$E16=""),"",MAX(0,N(IF($D16="",$C16,$D16))-N($E16))) | G16: =IF(OR($C16="",N($C$31)=0),"",N($C16)/$C$31)
B17: Videography | C17: 2200 | E17: 500 | F17: =IF(AND($B17="",$C17="",$D17="",$E17=""),"",MAX(0,N(IF($D17="",$C17,$D17))-N($E17))) | G17: =IF(OR($C17="",N($C$31)=0),"",N($C17)/$C$31)
B18: Music / DJ / band | C18: 2500 | E18: 500 | F18: =IF(AND($B18="",$C18="",$D18="",$E18=""),"",MAX(0,N(IF($D18="",$C18,$D18))-N($E18))) | G18: =IF(OR($C18="",N($C$31)=0),"",N($C18)/$C$31)
B19: Ceremony & officiant | C19: 400 | F19: =IF(AND($B19="",$C19="",$D19="",$E19=""),"",MAX(0,N(IF($D19="",$C19,$D19))-N($E19))) | G19: =IF(OR($C19="",N($C$31)=0),"",N($C19)/$C$31)
B20: Stationery & postage | C20: 700 | F20: =IF(AND($B20="",$C20="",$D20="",$E20=""),"",MAX(0,N(IF($D20="",$C20,$D20))-N($E20))) | G20: =IF(OR($C20="",N($C$31)=0),"",N($C20)/$C$31)
B21: Favors & gifts | C21: 350 | F21: =IF(AND($B21="",$C21="",$D21="",$E21=""),"",MAX(0,N(IF($D21="",$C21,$D21))-N($E21))) | G21: =IF(OR($C21="",N($C$31)=0),"",N($C21)/$C$31)
B22: Rings | C22: 2400 | F22: =IF(AND($B22="",$C22="",$D22="",$E22=""),"",MAX(0,N(IF($D22="",$C22,$D22))-N($E22))) | G22: =IF(OR($C22="",N($C$31)=0),"",N($C22)/$C$31)
B23: Transportation | C23: 900 | F23: =IF(AND($B23="",$C23="",$D23="",$E23=""),"",MAX(0,N(IF($D23="",$C23,$D23))-N($E23))) | G23: =IF(OR($C23="",N($C$31)=0),"",N($C23)/$C$31)
B24: Honeymoon | C24: 4500 | F24: =IF(AND($B24="",$C24="",$D24="",$E24=""),"",MAX(0,N(IF($D24="",$C24,$D24))-N($E24))) | G24: =IF(OR($C24="",N($C$31)=0),"",N($C24)/$C$31)
B25: Other / contingency | C25: 1000 | F25: =IF(AND($B25="",$C25="",$D25="",$E25=""),"",MAX(0,N(IF($D25="",$C25,$D25))-N($E25))) | G25: =IF(OR($C25="",N($C$31)=0),"",N($C25)/$C$31)
F26: =IF(AND($B26="",$C26="",$D26="",$E26=""),"",MAX(0,N(IF($D26="",$C26,$D26))-N($E26))) | G26: =IF(OR($C26="",N($C$31)=0),"",N($C26)/$C$31)
F27: =IF(AND($B27="",$C27="",$D27="",$E27=""),"",MAX(0,N(IF($D27="",$C27,$D27))-N($E27))) | G27: =IF(OR($C27="",N($C$31)=0),"",N($C27)/$C$31)
F28: =IF(AND($B28="",$C28="",$D28="",$E28=""),"",MAX(0,N(IF($D28="",$C28,$D28))-N($E28))) | G28: =IF(OR($C28="",N($C$31)=0),"",N($C28)/$C$31)
F29: =IF(AND($B29="",$C29="",$D29="",$E29=""),"",MAX(0,N(IF($D29="",$C29,$D29))-N($E29))) | G29: =IF(OR($C29="",N($C$31)=0),"",N($C29)/$C$31)
F30: =IF(AND($B30="",$C30="",$D30="",$E30=""),"",MAX(0,N(IF($D30="",$C30,$D30))-N($E30))) | G30: =IF(OR($C30="",N($C$31)=0),"",N($C30)/$C$31)
B31: TOTAL | C31: =SUM(C9:C30) | D31: =SUM(D9:D30) | E31: =SUM(E9:E30) | F31: =SUM(F9:F30) | G31: =SUM(G9:G30)
B33: 💡 Balance due uses the actual cost if entered, otherwise the estimate — minus deposits already paid.

Sheet Payment Tracker
B1: 🧾 PAYMENT TRACKER
B2: Every payment — amount, due date & paid status
B3: ✏️ Cream cells = your input 🔒 Grey cells = protected formulas • Novality Store Version 2.0
B8: Vendor | C8: Category | D8: Amount due | E8: Due date | F8: Amount paid | G8: Balance 🔒 | H8: Status | I8: Notes
B9: The Rosewood Estate | C9: Venue | D9: 6500 | E9: 46447 | F9: 2000 | G9: =IF(AND($D9="",$F9=""),"",MAX(0,N($D9)-N($F9)))
B10: Harvest & Vine Co. | C10: Catering | D10: 3000 | E10: 46492 | F10: 0 | G10: =IF(AND($D10="",$F10=""),"",MAX(0,N($D10)-N($F10)))
B11: Golden Hour Photo | C11: Photography | D11: 3200 | E11: 46508 | F11: 800 | G11: =IF(AND($D11="",$F11=""),"",MAX(0,N($D11)-N($F11)))
B12: Silver Sparrow DJ | C12: Music | D12: 2500 | E12: 46529 | F12: 0 | G12: =IF(AND($D12="",$F12=""),"",MAX(0,N($D12)-N($F12)))
B13: Bloom & Twine | C13: Florist | D13: 1500 | E13: 46497 | F13: 750 | G13: =IF(AND($D13="",$F13=""),"",MAX(0,N($D13)-N($F13)))
B14: Ivory & Oak Bridal | C14: Attire | D14: 1750 | E14: 46428 | F14: 1750 | G14: =IF(AND($D14="",$F14=""),"",MAX(0,N($D14)-N($F14)))
G15: =IF(AND($D15="",$F15=""),"",MAX(0,N($D15)-N($F15)))
G16: =IF(AND($D16="",$F16=""),"",MAX(0,N($D16)-N($F16)))
G17: =IF(AND($D17="",$F17=""),"",MAX(0,N($D17)-N($F17)))
G18: =IF(AND($D18="",$F18=""),"",MAX(0,N($D18)-N($F18)))
G19: =IF(AND($D19="",$F19=""),"",MAX(0,N($D19)-N($F19)))
G20: =IF(AND($D20="",$F20=""),"",MAX(0,N($D20)-N($F20)))
G21: =IF(AND($D21="",$F21=""),"",MAX(0,N($D21)-N($F21)))
G22: =IF(AND($D22="",$F22=""),"",MAX(0,N($D22)-N($F22)))
G23: =IF(AND($D23="",$F23=""),"",MAX(0,N($D23)-N($F23)))
G24: =IF(AND($D24="",$F24=""),"",MAX(0,N($D24)-N($F24)))
G25: =IF(AND($D25="",$F25=""),"",MAX(0,N($D25)-N($F25)))
G26: =IF(AND($D26="",$F26=""),"",MAX(0,N($D26)-N($F26)))
... G158: =IF(AND($D158="",$F158=""),"",MAX(0,N($D158)-N($F158)))
B159: TOTAL | D159: =SUM(D9:D158) | F159: =SUM(F9:F158) | G159: =SUM(G9:G158)

Sheet Budget Breakdown
B1: 📊 BUDGET BREAKDOWN BY CATEGORY
B2: Auto-totals from the Master Budget — with a live chart
B3: ✏️ Cream cells = your input 🔒 Grey cells = protected formulas • Novality Store Version 2.0
B8: Category | C8: Estimated 🔒 | D8: Actual 🔒 | E8: % of actual 🔒 | F8: Notes
B9: Venue & rental | C9: =SUMIF('Master Budget'!$B$9:$B$30,$B9,'Master Budget'!$C$9:$C$30) | D9: =SUMIF('Master Budget'!$B$9:$B$30,$B9,'Master Budget'!$D$9:$D$30) | E9: =IF(SUM($D$9:$D$25)=0,"",IF($D9=0,"",$D9/SUM($D$9:$D$25)))
B10: Catering & bar | C10: =SUMIF('Master Budget'!$B$9:$B$30,$B10,'Master Budget'!$C$9:$C$30) | D10: =SUMIF('Master Budget'!$B$9:$B$30,$B10,'Master Budget'!$D$9:$D$30) | E10: =IF(SUM($D$9:$D$25)=0,"",IF($D10=0,"",$D10/SUM($D$9:$D$25)))
B11: Wedding cake | C11: =SUMIF('Master Budget'!$B$9:$B$30,$B11,'Master Budget'!$C$9:$C$30) | D11: =SUMIF('Master Budget'!$B$9:$B$30,$B11,'Master Budget'!$D$9:$D$30) | E11: =IF(SUM($D$9:$D$25)=0,"",IF($D11=0,"",$D11/SUM($D$9:$D$25)))
B12: Bridal attire | C12: =SUMIF('Master Budget'!$B$9:$B$30,$B12,'Master Budget'!$C$9:$C$30) | D12: =SUMIF('Master Budget'!$B$9:$B$30,$B12,'Master Budget'!$D$9:$D$30) | E12: =IF(SUM($D$9:$D$25)=0,"",IF($D12=0,"",$D12/SUM($D$9:$D$25)))
B13: Groom & party attire | C13: =SUMIF('Master Budget'!$B$9:$B$30,$B13,'Master Budget'!$C$9:$C$30) | D13: =SUMIF('Master Budget'!$B$9:$B$30,$B13,'Master Budget'!$D$9:$D$30) | E13: =IF(SUM($D$9:$D$25)=0,"",IF($D13=0,"",$D13/SUM($D$9:$D$25)))
B14: Hair & makeup | C14: =SUMIF('Master Budget'!$B$9:$B$30,$B14,'Master Budget'!$C$9:$C$30) | D14: =SUMIF('Master Budget'!$B$9:$B$30,$B14,'Master Budget'!$D$9:$D$30) | E14: =IF(SUM($D$9:$D$25)=0,"",IF($D14=0,"",$D14/SUM($D$9:$D$25)))
B15: Flowers & décor | C15: =SUMIF('Master Budget'!$B$9:$B$30,$B15,'Master Budget'!$C$9:$C$30) | D15: =SUMIF('Master Budget'!$B$9:$B$30,$B15,'Master Budget'!$D$9:$D$30) | E15: =IF(SUM($D$9:$D$25)=0,"",IF($D15=0,"",$D15/SUM($D$9:$D$25)))
B16: Photography | C16: =SUMIF('Master Budget'!$B$9:$B$30,$B16,'Master Budget'!$C$9:$C$30) | D16: =SUMIF('Master Budget'!$B$9:$B$30,$B16,'Master Budget'!$D$9:$D$30) | E16: =IF(SUM($D$9:$D$25)=0,"",IF($D16=0,"",$D16/SUM($D$9:$D$25)))
B17: Videography | C17: =SUMIF('Master Budget'!$B$9:$B$30,$B17,'Master Budget'!$C$9:$C$30) | D17: =SUMIF('Master Budget'!$B$9:$B$30,$B17,'Master Budget'!$D$9:$D$30) | E17: =IF(SUM($D$9:$D$25)=0,"",IF($D17=0,"",$D17/SUM($D$9:$D$25)))
B18: Music / DJ / band | C18: =SUMIF('Master Budget'!$B$9:$B$30,$B18,'Master Budget'!$C$9:$C$30) | D18: =SUMIF('Master Budget'!$B$9:$B$30,$B18,'Master Budget'!$D$9:$D$30) | E18: =IF(SUM($D$9:$D$25)=0,"",IF($D18=0,"",$D18/SUM($D$9:$D$25)))
B19: Ceremony & officiant | C19: =SUMIF('Master Budget'!$B$9:$B$30,$B19,'Master Budget'!$C$9:$C$30) | D19: =SUMIF('Master Budget'!$B$9:$B$30,$B19,'Master Budget'!$D$9:$D$30) | E19: =IF(SUM($D$9:$D$25)=0,"",IF($D19=0,"",$D19/SUM($D$9:$D$25)))
B20: Stationery & postage | C20: =SUMIF('Master Budget'!$B$9:$B$30,$B20,'Master Budget'!$C$9:$C$30) | D20: =SUMIF('Master Budget'!$B$9:$B$30,$B20,'Master Budget'!$D$9:$D$30) | E20: =IF(SUM($D$9:$D$25)=0,"",IF($D20=0,"",$D20/SUM($D$9:$D$25)))
... B25: Other / contingency | C25: =SUMIF('Master Budget'!$B$9:$B$30,$B25,'Master Budget'!$C$9:$C$30) | D25: =SUMIF('Master Budget'!$B$9:$B$30,$B25,'Master Budget'!$D$9:$D$30) | E25: =IF(SUM($D$9:$D$25)=0,"",IF($D25=0,"",$D25/SUM($D$9:$D$25)))
B26: TOTAL | C26: =SUM(C9:C25) | D26: =SUM(D9:D25) | E26: =SUM(E9:E25)

Sheet Contributions
B1: 🤝 CASH FUND & CONTRIBUTIONS
B2: Who is contributing what towards the wedding
B3: ✏️ Cream cells = your input 🔒 Grey cells = protected formulas • Novality Store Version 2.0
B8: Contributor | C8: Side / relationship | D8: Amount | E8: Received? | F8: Date received | G8: Notes
B9: Mom & Dad Morgan | C9: Bride's parents | D9: 5000 | E9: Yes | F9: 46277
B10: Mom & Dad Lee | C10: Groom's parents | D10: 5000 | E10: Yes | F10: 46298
B11: Grandma Rose | C11: Bride's grandmother | D11: 500 | E11: Pending
B12: Self-funded | C12: The couple | D12: 6000 | E12: No
B39: TOTAL | D39: =SUM(D9:D38)
B41: Total wedding budget | C41: ='Master Budget'!$C$31
B42: Still needed to fund | C42: =MAX(0,N('Master Budget'!$C$31)-N($D$39))

Sheet Guest List
B1: 💌 GUEST LIST MASTER
B2: RSVP status, meal choice, +1s & table numbers — feeds the other guest tabs
B3: ✏️ Cream cells = your input 🔒 Grey cells = protected formulas • Novality Store Version 2.0
B5: INVITED | C5: =SUMPRODUCT(($B$9:$B$208<>"")*1) | D5: CONFIRMED | E5: =COUNTIF($G$9:$G$208,"Confirmed") | F5: DECLINED | G5: =COUNTIF($G$9:$G$208,"Declined") | H5: AWAITING | I5: =$C$5-$E$5-$G$5
B6: WITH +1 | C6: =COUNTIF($I$9:$I$208,"Yes") | D6: MEALS SET | E6: =SUMPRODUCT(($H$9:$H$208<>"")*($H$9:$H$208<>"TBD")) | F6: TABLES USED | G6: =SUMPRODUCT(($K$9:$K$208<>"")*1) | H6: ADDRESSES SET | I6: =SUMPRODUCT(($E$9:$E$208<>"")*1)
B8: Guest name | C8: Side | D8: Group / family | E8: Street address | F8: City / state | G8: RSVP status | H8: Meal choice | I8: +1? | J8: +1 name | K8: Table # | L8: Notes
B9: Ava Thompson | C9: Bride | D9: College friends | E9: 12 Maple Ave | F9: Asheville, NC | G9: Confirmed | H9: Chicken | I9: Yes | J9: Chris Thompson | K9: 3
B10: Noah Bennett | C10: Groom | D10: Family | E10: 88 Birch Rd | F10: Raleigh, NC | G10: Confirmed | H10: Beef | I10: No | K10: 5
B11: Olivia Carter | C11: Bride | D11: Family | E11: 4 Fern Hollow | F11: Asheville, NC | G11: Confirmed | H11: Vegetarian | I11: No | K11: 2
B12: Liam Nguyen | C12: Groom | D12: College friends | E12: 210 Cedar Ct | F12: Durham, NC | G12: Pending | H12: TBD | I12: No
B13: Emma Whitfield | C13: Bride | D13: Work | E13: 7 Laurel St | F13: Charlotte, NC | G13: Declined | I13: No
B14: Sophia Reyes | C14: Both | D14: Neighbors | E14: 150 Rose Ln | F14: Asheville, NC | G14: Confirmed | H14: Fish | I14: Yes | J14: Mateo Reyes | K14: 7
B15: Ethan Brooks | C15: Groom | D15: Family | E15: 31 Sycamore Way | F15: Greensboro, NC | G15: Pending | H15: TBD | I15: Yes | J15: Grace Brooks | K15: 5
B16: Mia Delgado | C16: Bride | D16: College friends | E16: 9 Poplar Dr | F16: Wilmington, NC | G16: Confirmed | H16: Gluten-Free | I16: No | K16: 3

Sheet Invitations Tracker
B1: 📬 SAVE-THE-DATE & INVITATION TRACKER
B2: Guest names pull in automatically from the Guest List
B3: ✏️ Cream cells = your input 🔒 Grey cells = protected formulas • Novality Store Version 2.0
B5: STCs SENT | C5: =SUMPRODUCT(($D$9:$D$208<>"")*1) | D5: INVITES SENT | E5: =SUMPRODUCT(($E$9:$E$208<>"")*1) | F5: RSVPs IN | G5: =COUNTIF($F$9:$F$208,"Yes") | H5: CONFIRMED | I5: =COUNTIF($G$9:$G$208,"Confirmed")
B8: Guest 🔒 | C8: Group 🔒 | D8: Save-the-date sent | E8: Invitation sent | F8: RSVP received? | G8: Response | H8: Reply date | I8: Notes
B9: =IF('Guest List'!$B9="","",'Guest List'!$B9) | C9: =IF('Guest List'!$D9="","",'Guest List'!$D9) | D9: 46327 | E9: 46402 | F9: Yes | G9: Confirmed | H9: 46415
B10: =IF('Guest List'!$B10="","",'Guest List'!$B10) | C10: =IF('Guest List'!$D10="","",'Guest List'!$D10) | D10: 46327 | E10: 46402 | F10: Yes | G10: Confirmed | H10: 46420
B11: =IF('Guest List'!$B11="","",'Guest List'!$B11) | C11: =IF('Guest List'!$D11="","",'Guest List'!$D11) | D11: 46327 | E11: 46402 | F11: No | G11: Pending
B12: =IF('Guest List'!$B12="","",'Guest List'!$B12) | C12: =IF('Guest List'!$D12="","",'Guest List'!$D12) | D12: 46327 | E12: 46402 | F12: No | G12: Declined
B13: =IF('Guest List'!$B13="","",'Guest List'!$B13) | C13: =IF('Guest List'!$D13="","",'Guest List'!$D13)
B14: =IF('Guest List'!$B14="","",'Guest List'!$B14) | C14: =IF('Guest List'!$D14="","",'Guest List'!$D14)
B15: =IF('Guest List'!$B15="","",'Guest List'!$B15) | C15: =IF('Guest List'!$D15="","",'Guest List'!$D15)
B16: =IF('Guest List'!$B16="","",'Guest List'!$B16) | C16: =IF('Guest List'!$D16="","",'Guest List'!$D16)
B17: =IF('Guest List'!$B17="","",'Guest List'!$B17) | C17: =IF('Guest List'!$D17="","",'Guest List'!$D17)
B18: =IF('Guest List'!$B18="","",'Guest List'!$B18) | C18: =IF('Guest List'!$D18="","",'Guest List'!$D18)
B19: =IF('Guest List'!$B19="","",'Guest List'!$B19) | C19: =IF('Guest List'!$D19="","",'Guest List'!$D19)
B20: =IF('Guest List'!$B20="","",'Guest List'!$B20) | C20: =IF('Guest List'!$D20="","",'Guest List'!$D20)
B21: =IF('Guest List'!$B21="","",'Guest List'!$B21) | C21: =IF('Guest List'!$D21="","",'Guest List'!$D21)
B22: =IF('Guest List'!$B22="","",'Guest List'!$B22) | C22: =IF('Guest List'!$D22="","",'Guest List'!$D22)
B23: =IF('Guest List'!$B23="","",'Guest List'!$B23) | C23: =IF('Guest List'!$D23="","",'Guest List'!$D23)
B24: =IF('Guest List'!$B24="","",'Guest List'!$B24) | C24: =IF('Guest List'!$D24="","",'Guest List'!$D24)
... B208: =IF('Guest List'!$B208="","",'Guest List'!$B208) | C208: =IF('Guest List'!$D208="","",'Guest List'!$D208)

Sheet Seating Chart
B1: 🪑 SEATING CHART PLANNER
B2: Six seats per table — assigned guests count automatically
B3: ✏️ Cream cells = your input 🔒 Grey cells = protected formulas • Novality Store Version 2.0
B5: CONFIRMED | C5: ='Guest List'!$E$5 | D5: SEATED | E5: =SUMPRODUCT(($D$9:$I$20<>"")*1) | F5: STILL TO SEAT | G5: =MAX(0,N('Guest List'!$E$5)-$E$5)
B8: Table # | C8: Table name | D8: Seat 1 | E8: Seat 2 | F8: Seat 3 | G8: Seat 4 | H8: Seat 5 | I8: Seat 6 | J8: Notes
B9: 1 | C9: Family of the bride
B10: 2 | C10: Family of the groom
B11: 3 | C11: College friends
B12: 4 | C12: Work friends
B13: 5 | C13: Childhood friends
B14: 6 | C14: The newlywed nook
B15: 7 | C15: Party people
B16: 8 | C16: Sweethearts' table
B17: 9 | C17: Out-of-towners
B18: 10 | C18: Vendor table
B19: 11
B20: 12
B22: 💡 Type guest names into the seats — the SEATED counter up top updates itself.

Sheet Hotel & Welcome Bags
B1: 🏨 HOTEL BLOCK & WELCOME BAGS
B2: Out-of-town guests, room blocks & welcome-bag delivery
B3: ✏️ Cream cells = your input 🔒 Grey cells = protected formulas • Novality Store Version 2.0
B8: Guest | C8: Out of town? | D8: Hotel / block | E8: Confirmation # | F8: Check-in | G8: Check-out | H8: Rooms | I8: Rate / night | J8: Est. total 🔒 | K8: Welcome bag? | L8: Bag contents | M8: Delivered? | N8: Notes
B9: Ava Thompson | C9: Yes | D9: Rosewood Inn | E9: RB-2214 | F9: 46528 | G9: 46530 | H9: 1 | I9: 149 | J9: =IF(OR($H9="",$I9=""),"",$H9*$I9) | K9: Local treats & itinerary | L9: Yes
B10: Ethan Brooks | C10: Yes | D10: Rosewood Inn | E10: RB-2215 | F10: 46528 | G10: 46530 | H10: 1 | I10: 149 | J10: =IF(OR($H10="",$I10=""),"",$H10*$I10) | L10: No
B11: Sophia Reyes | C11: Yes | D11: Rosewood Inn | E11: RB-2216 | F11: 46529 | G11: 46530 | H11: 1 | I11: 149 | J11: =IF(OR($H11="",$I11=""),"",$H11*$I11) | K11: Local treats & itinerary | L11: Yes
B12: Mia Delgado | C12: No | J12: =IF(OR($H12="",$I12=""),"",$H12*$I12) | L12: N/A
J13: =IF(OR($H13="",$I13=""),"",$H13*$I13)
J14: =IF(OR($H14="",$I14=""),"",$H14*$I14)
J15: =IF(OR($H15="",$I15=""),"",$H15*$I15)
J16: =IF(OR($H16="",$I16=""),"",$H16*$I16)
J17: =IF(OR($H17="",$I17=""),"",$H17*$I17)
J18: =IF(OR($H18="",$I18=""),"",$H18*$I18)
J19: =IF(OR($H19="",$I19=""),"",$H19*$I19)
J20: =IF(OR($H20="",$I20=""),"",$H20*$I20)
J21: =IF(OR($H21="",$I21=""),"",$H21*$I21)
J22: =IF(OR($H22="",$I22=""),"",$H22*$I22)
J23: =IF(OR($H23="",$I23=""),"",$H23*$I23)
J24: =IF(OR($H24="",$I24=""),"",$H24*$I24)
... J48: =IF(OR($H48="",$I48=""),"",$H48*$I48)
B49: TOTAL | H49: =SUM(H9:H48) | J49: =SUM(J9:J48)

Sheet Meal Count Summary
B1: 🍽️ MEAL COUNT SUMMARY
B2: Caterer-ready counts — updates from the Guest List meal column
B3: ✏️ Cream cells = your input 🔒 Grey cells = protected formulas • Novality Store Version 2.0
B8: Meal choice | C8: From guest list 🔒 | D8: Extras / +1s | E8: Total 🔒 | F8: Notes
B9: Chicken | C9: =COUNTIF('Guest List'!$H$9:$H$208,$B9) | E9: =N($C9)+N($D9)
B10: Beef | C10: =COUNTIF('Guest List'!$H$9:$H$208,$B10) | E10: =N($C10)+N($D10)
B11: Fish | C11: =COUNTIF('Guest List'!$H$9:$H$208,$B11) | E11: =N($C11)+N($D11)
B12: Vegetarian | C12: =COUNTIF('Guest List'!$H$9:$H$208,$B12) | E12: =N($C12)+N($D12)
B13: Vegan | C13: =COUNTIF('Guest List'!$H$9:$H$208,$B13) | E13: =N($C13)+N($D13)
B14: Gluten-Free | C14: =COUNTIF('Guest List'!$H$9:$H$208,$B14) | E14: =N($C14)+N($D14)
B15: Kids Meal | C15: =COUNTIF('Guest List'!$H$9:$H$208,$B15) | E15: =N($C15)+N($D15)
B16: Vendor meals | C16: =COUNTIF('Guest List'!$H$9:$H$208,$B16) | E16: =N($C16)+N($D16)
B17: GRAND TOTAL | C17: =SUM(C9:C16) | D17: =SUM(D9:D16) | E17: =SUM(E9:E16)
B19: 💡 Extras/+1s: kids' portions, vendor meals or last-minute additions.

Sheet Vendor Contacts
B1: 📋 VENDOR CONTACT SHEET
B2: All 11 vendor categories — contacts, contracts & balances
B3: ✏️ Cream cells = your input 🔒 Grey cells = protected formulas • Novality Store Version 2.0
B5: TOTAL VENDORS | C5: =SUMPRODUCT(($C$9:$C$58<>"")*1) | D5: BOOKED | E5: =COUNTIF($G$9:$G$58,"Booked")+COUNTIF($G$9:$G$58,"Contract Signed") | F5: TOTAL COST | G5: =SUM($I$9:$I$58)
B8: Category | C8: Company | D8: Contact person | E8: Phone | F8: Email | G8: Contract status | H8: Deposit paid | I8: Total cost | J8: Balance 🔒 | K8: Next payment due | L8: Notes
B9: Venue | C9: The Rosewood Estate | D9: Ms. Casey Reed | E9: (828) 555-0114 | F9: events@rosewood.com | G9: Contract Signed | H9: 2000 | I9: 8500 | J9: =IF($I9="","",MAX(0,N($I9)-N($H9)))
B10: Caterer | C10: Harvest & Vine Co. | D10: Mr. Daniel Cho | E10: (828) 555-0187 | F10: hello@harvestvine.co | G10: Booked | H10: 3000 | I10: 12000 | J10: =IF($I10="","",MAX(0,N($I10)-N($H10)))
B11: Photographer | C11: Golden Hour Photo | D11: Nora Blake | E11: (828) 555-0132 | F11: nora@goldenhour.photo | G11: Booked | H11: 800 | I11: 3200 | J11: =IF($I11="","",MAX(0,N($I11)-N($H11)))
B12: Videographer | C12: Reel Love Films | D12: Sam Ortiz | E12: (828) 555-0155 | F12: sam@reellove.film | G12: Quote Received | H12: 500 | I12: 2200 | J12: =IF($I12="","",MAX(0,N($I12)-N($H12)))
B13: Florist | C13: Bloom & Twine | D13: Ivy Laurent | E13: (828) 555-0166 | F13: ivy@bloomtwine.com | G13: Booked | H13: 700 | I13: 2800 | J13: =IF($I13="","",MAX(0,N($I13)-N($H13)))
B14: DJ / Band | C14: Silver Sparrow DJ | D14: Marcus Cole | E14: (828) 555-0178 | F14: book@silversparrow.dj | G14: Booked | H14: 500 | I14: 2500 | J14: =IF($I14="","",MAX(0,N($I14)-N($H14)))
B15: Officiant | C15: Rev. Harper | D15: Rev. A. Harper | E15: (828) 555-0121 | F15: revharper@officiate.org | G15: Contract Signed | I15: 400 | J15: =IF($I15="","",MAX(0,N($I15)-N($H15)))
B16: Hair & Makeup | C16: Glow Studio | D16: Priya Nair | E16: (828) 555-0143 | F16: priya@glowstudio.co | G16: Booked | H16: 150 | I16: 600 | J16: =IF($I16="","",MAX(0,N($I16)-N($H16)))
B17: Bakery (Cake) | C17: Sugarplum Cakery | D17: Lila Park | E17: (828) 555-0198 | F17: orders@sugarplum.co | G17: Booked | H17: 200 | I17: 650 | J17: =IF($I17="","",MAX(0,N($I17)-N($H17)))
B18: Transportation | C18: Blue Ridge Limo | D18: Tom Vance | E18: (828) 555-0109 | F18: fleet@blueridgelimo.com | G18: Inquiry | I18: 900 | J18: =IF($I18="","",MAX(0,N($I18)-N($H18)))
B19: Rentals | C19: Party Perfect Rentals | D19: Dana Fox | E19: (828) 555-0176 | F19: rent@partyperfect.com | G19: Negotiating | I19: 1200 | J19: =IF($I19="","",MAX(0,N($I19)-N($H19)))
J20: =IF($I20="","",MAX(0,N($I20)-N($H20)))
J21: =IF($I21="","",MAX(0,N($I21)-N($H21)))
J22: =IF($I22="","",MAX(0,N($I22)-N($H22)))
J23: =IF($I23="","",MAX(0,N($I23)-N($H23)))
J24: =IF($I24="","",MAX(0,N($I24)-N($H24)))
J25: =IF($I25="","",MAX(0,N($I25)-N($H25)))
J26: =IF($I26="","",MAX(0,N($I26)-N($H26)))
J27: =IF($I27="","",MAX(0,N($I27)-N($H27)))
J28: =IF($I28="","",MAX(0,N($I28)-N($H28)))
J29: =IF($I29="","",MAX(0,N($I29)-N($H29)))
J30: =IF($I30="","",MAX(0,N($I30)-N($H30)))
J31: =IF($I31="","",MAX(0,N($I31)-N($H31)))
... J58: =IF($I58="","",MAX(0,N($I58)-N($H58)))

Sheet Vendor Comparison
B1: ⚖️ VENDOR COMPARISON CHART
B2: Compare 2–3 options per category — savings calculate automatically
B3: ✏️ Cream cells = your input 🔒 Grey cells = protected formulas • Novality Store Version 2.0
B8: Category | C8: Option 1 | D8: Price 1 | E8: Option 2 | F8: Price 2 | G8: Option 3 | H8: Price 3 | I8: Chosen price | J8: You save 🔒 | K8: Winner & why
B9: Venue | C9: The Rosewood Estate | D9: 8500 | E9: Cedar Hollow Barn | F9: 7200 | G9: Glasshouse Downtown | H9: 11000 | I9: 8500 | J9: =IF($I9="","",MAX(N($D9),N($F9),N($H9))-$I9)
B10: Caterer | C10: Harvest & Vine Co. | D10: 12000 | E10: Fork & Flame | F10: 10500 | G10: Gather Table | H10: 13200 | I10: 12000 | J10: =IF($I10="","",MAX(N($D10),N($F10),N($H10))-$I10)
B11: Photographer | C11: Golden Hour Photo | D11: 3200 | E11: North Light Studio | F11: 2800 | G11: Ever After Co. | H11: 3900 | I11: 3200 | J11: =IF($I11="","",MAX(N($D11),N($F11),N($H11))-$I11)
B12: Videographer | C12: Reel Love Films | D12: 2200 | E12: Promise Films | F12: 1900 | I12: 1900 | J12: =IF($I12="","",MAX(N($D12),N($F12),N($H12))-$I12)
B13: DJ / Band | C13: Silver Sparrow DJ | D13: 2500 | E13: The Velvet Keys Band | F13: 4800 | I13: 2500 | J13: =IF($I13="","",MAX(N($D13),N($F13),N($H13))-$I13)
B14: Florist | C14: Bloom & Twine | D14: 2800 | E14: Petal & Stem | F14: 2400 | G14: Wildflora | H14: 3100 | I14: 2800 | J14: =IF($I14="","",MAX(N($D14),N($F14),N($H14))-$I14)
J15: =IF($I15="","",MAX(N($D15),N($F15),N($H15))-$I15)
J16: =IF($I16="","",MAX(N($D16),N($F16),N($H16))-$I16)
J17: =IF($I17="","",MAX(N($D17),N($F17),N($H17))-$I17)
J18: =IF($I18="","",MAX(N($D18),N($F18),N($H18))-$I18)
J19: =IF($I19="","",MAX(N($D19),N($F19),N($H19))-$I19)
J20: =IF($I20="","",MAX(N($D20),N($F20),N($H20))-$I20)

Sheet Dress Shopping Log
B1: 👰 BRIDE'S DRESS SHOPPING LOG
B2: Stores, styles, prices & the alterations timeline
B3: ✏️ Cream cells = your input 🔒 Grey cells = protected formulas • Novality Store Version 2.0
B8: Store / boutique | C8: Designer & style | D8: Price | E8: Appointment date | F8: Rating | G8: Say yes? | H8: Alterations? | I8: Alterations deadline | J8: Notes
B9: Ivory & Oak Bridal | C9: Maison Lilée — 'Amélie' | D9: 1800 | E9: 46279 | F9: 5 | G9: Yes! | H9: Yes | I9: 46487 | J9: THE one 💍
B10: Something Blue Atelier | C10: Vera Vow — 'Iris' | D10: 2200 | E10: 46297 | F10: 4 | G10: Maybe | H10: Yes | J10: Loved the neckline
B11: Classic Corner Bridal | C11: Sofia Sage — 'Willow' | D11: 1500 | E11: 46313 | F11: 3 | G11: No | H11: No | J11: Not me

Sheet Bridesmaid Dresses
B1: 💃 BRIDESMAID DRESS TRACKER
B2: Sizes, colors, orders & delivery status
B3: ✏️ Cream cells = your input 🔒 Grey cells = protected formulas • Novality Store Version 2.0
B8: Bridesmaid | C8: Dress style & color | D8: Size | E8: Price | F8: Ordered date | G8: Expected delivery | H8: Status | I8: Notes
B9: Olivia Carter | C9: Chiffon — Dusty rose | D9: 8 | E9: 165 | F9: 46397 | G9: 46461 | H9: Ordered
B10: Mia Delgado | C10: Chiffon — Dusty rose | D10: 6 | E10: 165 | F10: 46397 | G10: 46461 | H10: Shipped
B11: Grace Brooks | C11: Chiffon — Dusty rose | D11: 12 | E11: 165 | F11: 46399 | G11: 46466 | H11: To Order
B12: Chloe Fontaine | C12: Chiffon — Dusty rose | D12: 10 | E12: 165 | H12: To Order

Sheet Groom & Groomsmen
B1: 🤵 GROOM & GROOMSMEN ATTIRE
B2: Suit / tux details, rental vs purchase & fittings
B3: ✏️ Cream cells = your input 🔒 Grey cells = protected formulas • Novality Store Version 2.0
B8: Name | C8: Role | D8: Suit / tux style | E8: Color | F8: Rental or purchase | G8: Price | H8: Fitting date | I8: Pickup date | J8: Status | K8: Notes
B9: Jordan Lee | C9: Groom | D9: Midnight blue tuxedo | E9: Midnight | F9: Purchase | G9: 950 | H9: 46452 | I9: 46522 | J9: Ordered
B10: Chris Thompson | C10: Best Man | D10: Charcoal suit | E10: Charcoal | F10: Rental | G10: 180 | H10: 46452 | I10: 46525 | J10: Ordered
B11: Mateo Reyes | C11: Groomsman | D11: Charcoal suit | E11: Charcoal | F11: Rental | G11: 180 | H11: 46452 | I11: 46525 | J11: To Order
B12: Ethan Brooks | C12: Groomsman | D12: Charcoal suit | E12: Charcoal | F12: Rental | G12: 180 | H12: 46454 | I12: 46525 | J12: To Order

Sheet Hair & Makeup Trials
B1: 💅 HAIR & MAKEUP TRIAL NOTES
B2: Artists, looks, products & trial dates
B3: ✏️ Cream cells = your input 🔒 Grey cells = protected formulas • Novality Store Version 2.0
B8: Person | C8: Artist / studio | D8: Service / look | E8: Trial date | F8: Look & products used | G8: Trial price | H8: Booked for the day? | I8: Notes
B9: Bride | C9: Priya Nair — Glow Studio | D9: Soft glam + loose waves | E9: 46438 | F9: Dewy base · brown liner · rose lip | G9: 150 | H9: Yes
B10: Mother of the Bride | C10: Glow Studio | D10: Natural glam | E10: 46451 | F10: Soft bronze eye | G10: 85 | H10: Yes

Sheet Beauty Timeline
B1: ✨ BEAUTY TIMELINE
B2: Skincare, whitening, tanning & nails — dates auto-set from your wedding date
B3: ✏️ Cream cells = your input 🔒 Grey cells = protected formulas • Novality Store Version 2.0
B8: Beauty task | C8: Start by 🔒 | D8: Done? | E8: Notes
B9: Daily skincare routine starts | C9: =IF(Dashboard!$C$8="","",EDATE(Dashboard!$C$8,-6))
B10: Begin teeth whitening | C10: =IF(Dashboard!$C$8="","",EDATE(Dashboard!$C$8,-3))
B11: Final facial (no later!) | C11: =IF(Dashboard!$C$8="","",Dashboard!$C$8-14)
B12: Hair colour & trim | C12: =IF(Dashboard!$C$8="","",Dashboard!$C$8-30)
B13: Brow shaping | C13: =IF(Dashboard!$C$8="","",Dashboard!$C$8-7)
B14: Waxing appointments | C14: =IF(Dashboard!$C$8="","",Dashboard!$C$8-5)
B15: Spray tan trial | C15: =IF(Dashboard!$C$8="","",Dashboard!$C$8-21)
B16: Final spray tan | C16: =IF(Dashboard!$C$8="","",Dashboard!$C$8-2)
B17: Mani & pedi | C17: =IF(Dashboard!$C$8="","",Dashboard!$C$8-2)
B18: Eyelash extensions | C18: =IF(Dashboard!$C$8="","",Dashboard!$C$8-1)
C19: =IF(Dashboard!$C$8="","","")
C20: =IF(Dashboard!$C$8="","","")
C21: =IF(Dashboard!$C$8="","","")
C22: =IF(Dashboard!$C$8="","","")

Sheet Colors & Theme
B1: 🎨 COLOR PALETTE & THEME
B2: Swatches, keywords and materials that define the look
B3: ✏️ Cream cells = your input 🔒 Grey cells = protected formulas • Novality Store Version 2.0
B5: THE PALETTE — recolour any swatch to suit you
B7: Blush | C7: Dusty rose | D7: Rose gold | E7: Sage | F7: Gold | G7: Champagne | H7: Ivory | I7: Plum
B8: Bridesmaid dresses | C8: Linens | D8: Stationery foil | E8: Greenery | F8: Candle holders | G8: Cake details | H8: Tablecloths | I8: Accent signage
B9: ↑ colour name
B10: ↑ where it's used
B12: THEME KEYWORDS
B13: Keyword | C13: Use it for
B14: Garden party | C14: Florals, arch, stationery borders
B15: Heirloom | C15: Rings, cake topper, tableware
B16: Candlelit | C16: Reception lighting, aisle glow
B17: Organic | C17: Loose arrangements, flowing ribbon
B21: TEXTURES & MATERIALS
B22: Material | C22: Where it appears
B23: Linen | C23: Tablecloths & napkins
B24: Velvet | C24: Ribbon on bouquets
B25: Brass | C25: Candlesticks & arch detail
B26: Handmade paper | C26: Menus & place cards
B30: DESIGN NOTES
B31: Keep ceremony décor low so it never blocks the mountain view…

Sheet Floral Planner
B1: 🌸 FLORAL ARRANGEMENT PLANNER
B2: Bouquets, ceremony flowers, centerpieces & costs
B3: ✏️ Cream cells = your input 🔒 Grey cells = protected formulas • Novality Store Version 2.0
B8: Arrangement | C8: Flowers / details | D8: Qty | E8: Est. each | F8: Est. total 🔒 | G8: Actual | H8: Variance 🔒 | I8: Notes
B9: Bridal bouquet | C9: Garden roses, ranunculus, trailing ribbon | D9: 1 | E9: 180 | F9: =IF(OR($D9="",$E9=""),"",$D9*$E9) | H9: =IF($G9="","",$G9-N($F9))
B10: Bridesmaid bouquets | C10: Smaller version of bridal | D10: 4 | E10: 65 | F10: =IF(OR($D10="",$E10=""),"",$D10*$E10) | H10: =IF($G10="","",$G10-N($F10))
B11: Boutonnieres | C11: Spray rose & greenery | D11: 8 | E11: 12 | F11: =IF(OR($D11="",$E11=""),"",$D11*$E11) | H11: =IF($G11="","",$G11-N($F11))
B12: Corsages | C12: Grandmothers & mothers | D12: 4 | E12: 18 | F12: =IF(OR($D12="",$E12=""),"",$D12*$E12) | H12: =IF($G12="","",$G12-N($F12))
B13: Ceremony arch | C13: Organic asymmetric install | D13: 1 | E13: 850 | F13: =IF(OR($D13="",$E13=""),"",$D13*$E13) | H13: =IF($G13="","",$G13-N($F13))
B14: Aisle arrangements | C14: Mason jar posies on shepherd hooks | D14: 10 | E14: 35 | F14: =IF(OR($D14="",$E14=""),"",$D14*$E14) | H14: =IF($G14="","",$G14-N($F14))
B15: Centerpieces | C15: Low compote + candles | D15: 14 | E15: 55 | F15: =IF(OR($D15="",$E15=""),"",$D15*$E15) | H15: =IF($G15="","",$G15-N($F15))
B16: Cake flowers | C16: Fresh blooms for tiers | D16: 1 | E16: 45 | F16: =IF(OR($D16="",$E16=""),"",$D16*$E16) | H16: =IF($G16="","",$G16-N($F16))
B17: Flower girl petals | C17: Blush freeze-dried petals | D17: 2 | E17: 15 | F17: =IF(OR($D17="",$E17=""),"",$D17*$E17) | H17: =IF($G17="","",$G17-N($F17))
B18: Extra greenery | C18: Eucalyptus bunches for signage | D18: 6 | E18: 12 | F18: =IF(OR($D18="",$E18=""),"",$D18*$E18) | H18: =IF($G18="","",$G18-N($F18))
F19: =IF(OR($D19="",$E19=""),"",$D19*$E19) | H19: =IF($G19="","",$G19-N($F19))
F20: =IF(OR($D20="",$E20=""),"",$D20*$E20) | H20: =IF($G20="","",$G20-N($F20))
F21: =IF(OR($D21="",$E21=""),"",$D21*$E21) | H21: =IF($G21="","",$G21-N($F21))
F22: =IF(OR($D22="",$E22=""),"",$D22*$E22) | H22: =IF($G22="","",$G22-N($F22))
F23: =IF(OR($D23="",$E23=""),"",$D23*$E23) | H23: =IF($G23="","",$G23-N($F23))
F24: =IF(OR($D24="",$E24=""),"",$D24*$E24) | H24: =IF($G24="","",$G24-N($F24))
B25: TOTAL | F25: =SUM(F9:F24) | G25: =SUM(G9:G24) | H25: =SUM(H9:H24)

Sheet Ceremony Décor
B1: ⛪ CEREMONY DÉCOR CHECKLIST
B2: Arch, aisle, signage & programs
B3: ✏️ Cream cells = your input 🔒 Grey cells = protected formulas • Novality Store Version 2.0
B8: Item | C8: Vendor / owner | D8: Est. cost | E8: Actual cost | F8: Done? | G8: Notes
B9: Arbor / arch | C9: Bloom & Twine | D9: 850
B10: Aisle markers | C10: Bloom & Twine | D10: 350
B11: Aisle runner | C11: Rentals | D11: 60
B12: Welcome sign | C12: Handmade paper co. | D12: 120
B13: Program table | D13: 40
B14: Guest book & pen | D14: 55
B15: Candles & lanterns | C15: Party Perfect Rentals | D15: 90
B16: Entrance florals | C16: Bloom & Twine | D16: 150
B17: Unity ceremony setup | D17: 25
B24: TOTAL | D24: =SUM(D9:D23) | E24: =SUM(E9:E23)

Sheet Reception Décor
B1: 🥂 RECEPTION DÉCOR CHECKLIST
B2: Centerpieces, lighting, draping & backdrop
B3: ✏️ Cream cells = your input 🔒 Grey cells = protected formulas • Novality Store Version 2.0
B8: Item | C8: Vendor / owner | D8: Est. cost | E8: Actual cost | F8: Done? | G8: Notes
B9: Centerpieces | C9: Bloom & Twine | D9: 770
B10: Table numbers | C10: Handmade paper co. | D10: 45
B11: Place cards | C11: Handmade paper co. | D11: 60
B12: Sweetheart table | C12: DIY | D12: 80
B13: Cake table styling | C13: DIY | D13: 40
B14: Dessert bar | D14: 120
B15: String lights / festoons | C15: Party Perfect Rentals | D15: 220
B16: Draping & backdrop | C16: Party Perfect Rentals | D16: 350
B17: Photo booth backdrop | D17: 95
B18: Lounge furniture | C18: Rentals | D18: 260
B19: Dance floor wrap | D19: 150
B20: Bar signage | D20: 35
B27: TOTAL | D27: =SUM(D9:D26) | E27: =SUM(E9:E26)

Sheet Stationery Checklist
B1: ✉️ STATIONERY SUITE CHECKLIST
B2: Invitations, RSVPs, menus, place cards, programs & signage
B3: ✏️ Cream cells = your input 🔒 Grey cells = protected formulas • Novality Store Version 2.0
B8: Item | C8: Vendor | D8: Qty | E8: Cost | F8: Ordered date | G8: Delivered? | H8: Notes
B9: Save-the-dates | C9: Handmade paper co. | D9: 80 | E9: 180
B10: Invitations & RSVP cards | C10: Handmade paper co. | D10: 80 | E10: 340
B11: Detail / info cards | C11: Handmade paper co. | D11: 80 | E11: 90
B12: Menus | C12: Handmade paper co. | D12: 15 | E12: 60
B13: Place cards | C13: Handmade paper co. | D13: 90 | E13: 75
B14: Programs | C14: Handmade paper co. | D14: 80 | E14: 85
B15: Welcome sign print | C15: Poster shop | D15: 1 | E15: 55
B16: Bar & dessert signs | C16: DIY | D16: 3 | E16: 25
B17: Thank-you cards | C17: Handmade paper co. | D17: 80 | E17: 95
B18: Stamps & envelopes | C18: Post office | D18: 1 | E18: 120
B25: TOTAL | E25: =SUM(E9:E24)

Sheet Menu Planning
B1: 🍽️ MENU PLANNING
B2: Appetizers, mains, sides & desserts
B3: ✏️ Cream cells = your input 🔒 Grey cells = protected formulas • Novality Store Version 2.0
B8: Course | C8: Dish | D8: Dietary tags | E8: Servings | F8: Sourced from | G8: Notes
B9: Appetizer
B10: Appetizer
B11: Appetizer
B12: Main
B13: Main
B14: Main
B15: Side
B16: Side
B17: Dessert
B18: Dessert
B19: Kids meal
B20: Late-night

Sheet Cake Design
B1: 🎂 CAKE DESIGN & FLAVOR NOTES
B2: Tiers, flavors & payment
B3: ✏️ Cream cells = your input 🔒 Grey cells = protected formulas • Novality Store Version 2.0
B5: THE BAKERY
B6: Bakery | C6: Sugarplum Cakery
B7: Delivery time | C7: 1:00 PM (before reception)
B8: Delivery & setup fee | C8: 45
B10: CAKE TIERS
B11: Tier | C11: Flavor | D11: Filling | E11: Frosting | F11: Serves | G11: Notes
B12: Tier 1 (bottom) | C12: Lemon elderflower | D12: Vanilla bean cream | E12: Swiss meringue buttercream | F12: 60
B13: Tier 2 | C13: Almond champagne | D13: Raspberry preserve | E13: Swiss meringue buttercream | F13: 40
B14: Tier 3 (top) | C14: Chocolate salted caramel | D14: Salted caramel | E14: Chocolate ganache | F14: 20
B16: PAYMENT
B17: Price quoted | C17: 650
B18: Deposit paid | C18: 200
B19: Balance due 🔒 | C19: =IF(AND($C$17="",$C$18=""),"",MAX(0,N($C$17)-N($C$18)))
B21: DESIGN & SETUP NOTES
B22: Semi-naked finish with fresh blush blooms matching the bouquets; gold leaf on tier 2; cake topper 'M & L'.

Sheet Bar & Drinks
B1: 🍹 BAR & DRINK MENU PLANNER
B2: Signature cocktails, wine, beer & non-alcoholic
B3: ✏️ Cream cells = your input 🔒 Grey cells = protected formulas • Novality Store Version 2.0
B8: Type | C8: Item / brand | D8: Qty needed | E8: Est. cost | F8: Supplier | G8: Served when | H8: Notes
B9: Signature cocktail | C9: The Rosewood Fizz — gin, grapefruit, rosemary | D9: 120 | E9: 340 | F9: Harvest & Vine Co. | G9: Cocktail hour
B10: Signature mocktail | C10: Blush Spritz — raspberry, elderflower, soda | D10: 60 | E10: 60 | F10: Harvest & Vine Co. | G10: All night
B11: Beer | C11: Local IPA + lager kegs | D11: 3 | E11: 420 | F11: Blue Ridge Brewing | G11: Reception
B12: Wine — red | C12: Pinot noir (case of 12) | D12: 2 | E12: 240 | F12: Vine & Barrel | G12: Dinner
B13: Wine — white | C13: Sauvignon blanc (case of 12) | D13: 2 | E13: 220 | F13: Vine & Barrel | G13: Dinner
B14: Wine — sparkling | C14: Prosecco for toasts (case) | D14: 1 | E14: 150 | F14: Vine & Barrel | G14: Toasts
B15: Spirits & mixers | C15: Whiskey, vodka, tonic, citrus | D15: 1 | E15: 380 | F15: Harvest & Vine Co. | G15: Reception
B16: Soft drinks | C16: Sodas, lemonade, iced tea | D16: 1 | E16: 90 | F16: Harvest & Vine Co. | G16: All night
B17: Coffee & tea | C17: Decaf bar with late-night dessert | D17: 1 | E17: 75 | F17: Harvest & Vine Co. | G17: Dessert
B23: TOTAL | E23: =SUM(E9:E22)

Sheet Tasting Notes
B1: 🥄 TASTING APPOINTMENT NOTES
B2: Rate what you taste — then book the winner
B3: ✏️ Cream cells = your input 🔒 Grey cells = protected formulas • Novality Store Version 2.0
B8: Date | C8: Vendor | D8: What we tasted | E8: Taste | F8: Presentation | G8: Winner? | H8: Notes
B9: 46409 | C9: Harvest & Vine Co. | D9: Tasting menu: short rib, salmon, pear salad | E9: 5 | F9: 5 | G9: Yes | H9: Booked — short rib is unreal
B10: 46426 | C10: Sugarplum Cakery | D10: Cake: lemon elderflower + chocolate caramel | E10: 5 | F10: 4 | G10: Yes | H10: Lemon tier won everyone over

Sheet Late-Night Snacks
B1: 🌙 LATE-NIGHT SNACK IDEAS
B2: The midnight save — ideas, quantities & costs
B3: ✏️ Cream cells = your input 🔒 Grey cells = protected formulas • Novality Store Version 2.0
B8: Snack idea | C8: Vendor | D8: Qty | E8: Est. cost | F8: Chosen? | G8: Notes
B9: Slider truck | C9: Bun & Run | D9: 75 | E9: 450
B10: Pizza slices | C10: Slice of Heaven | D10: 80 | E10: 320
B11: Churros | C11: Sweet carts | D11: 60 | E11: 210
B12: Milkshakes | C12: Sugarplum Cakery | D12: 50 | E12: 175
B13: Ramen cups | C13: Self-serve station | D13: 40 | E13: 60
B14: Mini tacos | C14: Fork & Flame | D14: 70 | E14: 280
B15: Donut wall | C15: Glazed & Amused | D15: 60 | E15: 240
B16: Pretzel station | C16: Pop & Pretzel | D16: 50 | E16: 150
B21: TOTAL | E21: =SUM(E9:E20)

Sheet Wedding Day Timeline
B1: ⏰ WEDDING DAY TIMELINE
B2: Hour-by-hour from getting ready to send-off
B3: ✏️ Cream cells = your input 🔒 Grey cells = protected formulas • Novality Store Version 2.0
B8: Time | C8: Event | D8: Who's involved | E8: Location | F8: Lead / vendor | G8: Notes
B9: 7:00 AM | C9: Wake up, breakfast & hydrate | D9: Couple | E9: Getting-ready suite | F9: —
B10: 7:30 AM | C10: Hair & makeup begins | D10: Wedding party | E10: Getting-ready suite | F10: Glow Studio
B11: 9:30 AM | C11: Photographer arrives — detail shots | D11: Photographer | E11: Suite | F11: Golden Hour Photo
B12: 10:30 AM | C12: Get dressed · first look | D12: Couple | E12: Garden
B13: 11:00 AM | C13: Wedding party photos | D13: Photographer | E13: Estate grounds
B14: 11:45 AM | C14: Family formal photos | D14: Families | E14: Ceremony lawn | F14: See Family Photos tab
B15: 12:30 PM | C15: Light lunch & touch-ups | D15: Everyone | E15: Suite
B16: 1:30 PM | C16: Guests arrive · prelude music | D16: Guests | E16: Ceremony lawn | F16: Silver Sparrow DJ
B17: 2:00 PM | C17: CEREMONY 💍 | D17: Everyone | E17: Ceremony lawn
B18: 2:45 PM | C18: Cocktail hour · couple portraits | D18: Guests / couple | E18: Terrace
B19: 4:00 PM | C19: Grand entrance & first dance | D19: Couple | E19: Reception barn
B20: 4:15 PM | C20: Dinner service | D20: Guests | E20: Reception barn | F20: Harvest & Vine
B21: 5:15 PM | C21: Toasts | D21: Best man & MOH | E21: Reception barn
B22: 6:00 PM | C22: Cake cutting | D22: Couple | E22: Cake table
B23: 6:15 PM | C23: Open dance floor | D23: Everyone | E23: Reception barn | F23: DJ
B24: 8:00 PM | C24: Bouquet & garter toss | E24: Dance floor
B25: 8:30 PM | C25: Late-night snack surprise | D25: Everyone | E25: Reception barn | F25: Slider truck
B26: 9:30 PM | C26: Last slow dance | D26: Everyone | E26: Reception barn
B27: 10:00 PM | C27: Sparkler send-off ✨ | D27: Everyone | E27: Estate drive

Sheet Rehearsal Dinner
B1: 🍝 REHEARSAL DINNER PLANNER
B2: Guest list, venue, menu & toasts
B3: ✏️ Cream cells = your input 🔒 Grey cells = protected formulas • Novality Store Version 2.0
B5: THE PLAN
B6: Date | C6: Friday 21 May 2027
B7: Time | C7: 6:30 PM
B8: Venue | C8: Copper Kettle Kitchen
B9: Hosted by | C9: The Lee family
B10: Menu theme | C10: Family-style Italian
B12: GUEST LIST
B13: Guest / group | C13: Party | D13: Attending? | E13: Notes
B14: Jordan Lee | C14: The couple
B15: Alex Morgan | C15: The couple
B16: Rev. Harper | C16: Officiant + spouse
B17: Parents & grandparents | C17: Both families
B18: Wedding party + plus-ones | C18: Wedding party
B19: Readers & ring bearers | C19: Ceremony roles
B28: TOAST SCHEDULE
B29: Time | C29: Speaker | D29: Topic / notes
B30: 6:45 PM | C30: Host welcome | D30: Mr. Lee
B31: 7:30 PM | C31: Parents' toast | D31: Both sets of parents
B32: 8:15 PM | C32: Couple thanks everyone | D32: Jordan & Alex

Sheet Ceremony Order
B1: 💍 CEREMONY ORDER OF EVENTS
B2: Processional, readings, vows, ring exchange & recessional
B3: ✏️ Cream cells = your input 🔒 Grey cells = protected formulas • Novality Store Version 2.0
B8: # | C8: Moment | D8: Music / reading | E8: Participants | F8: Notes
B9: 1 | C9: Pre-service prelude | D9: Canon in D (instrumental) | E9: DJ | F9: Starts 30 min before
B10: 2 | C10: Family seating | D10: Landslide (instrumental) | E10: Ushers
B11: 3 | C11: Wedding party processional | D11: Can't Help Falling in Love — Kina Grannis | E11: Wedding party
B12: 4 | C12: Bride's processional | D12: At Last — string quartet version | E12: Alex & escort
B13: 5 | C13: Words of welcome | E13: Rev. Harper
B14: 6 | C14: First reading | D14: The Art of Marriage | E14: Ava's sister
B15: 7 | C15: Second reading | D15: Sonnet 116 — Shakespeare | E15: Noah's brother
B16: 8 | C16: Vows | D16: Handwritten | E16: The couple | F16: See Vow Worksheet
B17: 9 | C17: Ring exchange | D17: Soft instrumental | E17: The couple | F17: Ring bearer
B18: 10 | C18: Unity ritual | D18: Handfasting with family ribbons | E18: The couple
B19: 11 | C19: Pronouncement & first kiss | E19: Rev. Harper
B20: 12 | C20: Recessional | D20: Signed, Sealed, Delivered — Stevie Wonder | E20: Everyone

Sheet Reception Timeline
B1: 🕺 RECEPTION TIMELINE
B2: Grand entrance, first dance, toasts, cake cutting & bouquet toss
B3: ✏️ Cream cells = your input 🔒 Grey cells = protected formulas • Novality Store Version 2.0
B8: Time | C8: Event | D8: DJ cue / song | E8: Who | F8: Notes
