Workbook
Name Project_Status: Lookups!$A$5:$A$9
Name Project_Phase: Lookups!$B$5:$B$15
Name Room_Type: Lookups!$C$5:$C$22
Name Room_Status: Lookups!$D$5:$D$9
Name Design_Style: Lookups!$E$5:$E$14
Name Design_Item: Lookups!$F$5:$F$17
Name Budget_Category: Lookups!$G$5:$G$14
Name Expense_Status: Lookups!$H$5:$H$8
Name Payment_Method: Lookups!$I$5:$I$10
Name Trade: Lookups!$J$5:$J$21
Name Task_Status: Lookups!$K$5:$K$10
Name Priority: Lookups!$L$5:$L$8
Name Material_Status: Lookups!$M$5:$M$13
Name Doc_Category: Lookups!$N$5:$N$18
Name Role: Lookups!$O$5:$O$13
Name Quote_Status: Lookups!$P$5:$P$10
Name Job_Status: Lookups!$Q$5:$Q$10
Name Insp_Result: Lookups!$R$5:$R$8
Name Payment_Status: Lookups!$S$5:$S$9
Name CO_Status: Lookups!$T$5:$T$9
Name Permit_Status: Lookups!$U$5:$U$10
Name Maint_Status: Lookups!$V$5:$V$9
Name Insight_Severity: Lookups!$W$5:$W$8
Name Insight_Status: Lookups!$X$5:$X$9
Name Channel: Lookups!$Y$5:$Y$11
Name Currency: Lookups!$Z$5:$Z$11
Name Language: Lookups!$AA$5:$AA$11
Name Property_Type: Lookups!$AB$5:$AB$10
Name ActiveProject: Settings!$B$9
Name HomeownerName: Settings!$B$8
Name CurSym: Settings!$B$12
Name ContingencyPct: Settings!$B$14
Name AsOfDate: Settings!$B$16
Name ContingencyFloor: Settings!$B$22
Name OverrunAlert: Settings!$B$23
Name CompanyName: Settings!$B$5
Name TaxRate: Settings!$B$18

Sheet Start Here
A1: START HERE
A2: Read this first · then open Dashboard · upload this file to Google Drive to get a Google Sheet
A4: Novality Store · Home Renovation Management System
A5: A digital twin of the home: every room, material, contractor, expense, document, task, photo, warranty and maintenance activity is connected to a place in the house. This workbook is the complete operating system for a renovation — from first idea through handover and aftercare.
A8: How to use (Excel) | F8: How to use (Google Sheets)
A9: 1. Enable editing / calculation (Formulas → Automatic). | F9: 1. Upload this .xlsx to Google Drive → Open with Google Sheets.
A10: 2. Open Settings. Set Active Project ID (PRJ-001 or PRJ-002). | F10: 2. File → Save as Google Sheets (keeps formulas, colors, charts).
A11: 3. Work in the yellow-ivory input cells. Grey-sand cells are formulas — don't type over them. | F11: 3. Extensions → Apps Script → paste google_apps_script/Code.gs.
A12: 4. Add rows above the last data row; copy the formula cells down. | F12: 4. Reload the sheet. A “Novality Store” menu appears.
A13: 5. Use column filters on every register. Status columns are color-coded. | F13: 5. Formula cells stay locked in Excel. Google Sheets: Data → Protect sheets.
A14: 6. Dashboard, Finance and Admin recalculate from the registers. | F14: 6. Share with contractors as Commenter or custom-filtered views.
A15: 7. File → Print uses tabloid landscape and branded headers. | F15: 7. Optional: File → Download to keep an Excel archive.
A18: Color system
A19: Primary #16352F Forest | C19: Secondary #E8DDCB Sand | E19: Accent #C86B4A Terracotta | G19: Background #F8F6F1 Ivory
A20: Success #719B7A Sage | C20: Warning #D99A3D Amber | E20: Danger #C75C5C Muted red | G20: Formula cells (do not type)
A22: Module index (click to jump)
A23: Sheet | B23: What it holds | F23: Sheet | G23: What it holds
A24: Dashboard | B24: Homeowner overview, KPIs, alerts, next tasks | F24: Messages | G24: Threaded communication log
A25: Projects | B25: Multi-project register with live spend | F25: Inventory | G25: Home contents for insurance
A26: Rooms | B26: Spaces, measurements, budgets, photos | F26: Maintenance | G26: Aftercare hub + reminders
A27: Design Studio | B27: Mood boards, palettes, 2D/3D, AI concepts | F27: Inspections | G27: City and independent
A28: AI Insights | B28: Assistant recommendations and savings | F28: Payments | G28: Draws and aging
A29: Budget | B29: Category + room plan vs actual | F29: Change Orders | G29: Scope / cost / schedule deltas
A30: Expenses | B30: Transaction log (Planned / Committed / Paid) | F30: Permits | G30: Authorities and expirations
A31: Finance | B31: Charts, monthly cash, smart alerts | F31: Warranties | G31: Labor and product coverage
A32: Contractors | B32: Profiles + Quality / On-time / Budget / Comms score | F32: Calendar | G32: Visits and deadlines
A33: Quotes | B33: Bid comparison and award | F33: Notifications | G33: Alert queue
A34: Jobs | B34: Assignments, milestones, balances | F34: Users | G34: Nine roles
... A40: Documents | B40: Project vault + expiry alerts | F40: Roles & Permissions | G40: Matrix of who can do what
A43: Sample story already loaded
A44: Alex Rivera is renovating 1847 Maplewood Drive, Portland (PRJ-001, $85,000, 72% complete, Construction phase). Kitchen boxes are going in this week; primary bath is on punch list after an AI-led swap from marble to porcelain (about 18% saved on that category). Contingency has dipped under 10%, so the exterior water feature is on hold. A second property — the Columbia Gorge cabin bath (PRJ-002) — is in design so you can see multi-property. Today in the file is 24 August 2026. Change Settings → Today if you reopen this later.
A49: Roles in this system
A50: Homeowner | B50: Admin | C50: Project Manager | D50: Interior Designer | E50: Contractor | F50: Subcontractor | G50: Supplier | H50: Inspector | I50: Accountant

Sheet Dashboard
A1: DASHBOARD
A2: Homeowner overview · live formulas · switch Active Project on Settings
A4: ="Good day, " & HomeownerName & " · " & TEXT(AsOfDate,"DDDD, D MMMM YYYY")
A5: ="YOUR RENOVATION · " & IFERROR(INDEX(Projects!C:C,MATCH(ActiveProject,Projects!A:A,0)),ActiveProject) & " · " & IFERROR(INDEX(Projects!F:F,MATCH(ActiveProject,Projects!A:A,0)),"")
A7: PROGRESS | E7: PHASE | H7: BUDGET | K7: SPENT
A8: =IFERROR(INDEX(Projects!P:P,MATCH(ActiveProject,Projects!A:A,0)),0) | E8: =IFERROR(INDEX(Projects!F:F,MATCH(ActiveProject,Projects!A:A,0)),"—") | H8: =IFERROR(INDEX(Projects!J:J,MATCH(ActiveProject,Projects!A:A,0)),0) | K8: =IFERROR(SUMIFS(Expenses!H:H,Expenses!C:C,ActiveProject,Expenses!J:J,"Paid"),0)
A9: =REPT("█",ROUND(A8*20,0))&REPT("░",20-ROUND(A8*20,0)) | E9: =IFERROR(INDEX(Projects!E:E,MATCH(ActiveProject,Projects!A:A,0)),"") | H9: Planned | K9: Paid to date
A11: COMMITTED | D11: REMAINING | G11: OPEN TASKS | J11: OVERDUE
A12: =IFERROR(SUMIFS(Expenses!H:H,Expenses!C:C,ActiveProject,Expenses!J:J,"Committed"),0) | D12: =H8-K8-A12 | G12: =COUNTIFS(Tasks!B:B,ActiveProject,Tasks!H:H,"<>Completed") | J12: =COUNTIFS(Tasks!B:B,ActiveProject,Tasks!H:H,"<>Completed",Tasks!K:K,"<"&AsOfDate)
A13: Not yet paid | D13: Still available | G13: Not completed | J13: Past deadline
A15: ATTENTION | H15: NEXT UP
A16: =IF((K8+A12)>H8,"⚠ Project is over the planned budget.","") | H16: When | I16: Task | J16: Room | K16: Owner | L16: Status
A17: =IF(Finance!D10<H8*ContingencyFloor,"🔴 Contingency has fallen below 10%. Freeze non-critical extras.","") | H17: =IFERROR(FILTER(Tasks!K5:K200,(Tasks!B5:B200=ActiveProject)*(Tasks!H5:H200<>"Completed")),"") | I17: =IFERROR(FILTER(Tasks!D5:D200,(Tasks!B5:B200=ActiveProject)*(Tasks!H5:H200<>"Completed")),"") | J17: =IFERROR(FILTER(Tasks!C5:C200,(Tasks!B5:B200=ActiveProject)*(Tasks!H5:H200<>"Completed")),"") | K17: =IFERROR(FILTER(Tasks!F5:F200,(Tasks!B5:B200=ActiveProject)*(Tasks!H5:H200<>"Completed")),"") | L17: =IFERROR(FILTER(Tasks!H5:H200,(Tasks!B5:B200=ActiveProject)*(Tasks!H5:H200<>"Completed")),"")
A18: =IF(COUNTIFS(Tasks!B:B,ActiveProject,Tasks!Q:Q,"Overdue")>0,"⚠ "&COUNTIFS(Tasks!B:B,ActiveProject,Tasks!Q:Q,"Overdue")&" overdue task(s).","")
A19: =IF(COUNTIFS(Materials!B:B,ActiveProject,Materials!P:P,"Backordered")>0,"⚠ Material backorder: "&COUNTIFS(Materials!B:B,ActiveProject,Materials!P:P,"Backordered")&" line(s).","")
A20: =IF(COUNTIFS(Documents!B:B,ActiveProject,Documents!N:N,"Expiring")+COUNTIFS(Documents!B:B,ActiveProject,Documents!N:N,"Expired")>0,"⚠ Document expiry needs attention.","")
A21: =IF(COUNTIFS('Change Orders'!B:B,ActiveProject,'Change Orders'!I:I,"Submitted")>0,"⚠ Change order awaiting approval.","")
A22: =IF(COUNTA(A16:A21)=0,"🟢 Nothing urgent. You're clear for the week.","")
A24: RECENT EXPENSES | H24: ROOMS
A25: Date | B25: Vendor | C25: Description | D25: Amount | E25: Status | H25: Room | I25: Status | J25: Budget | K25: Spent | L25: %
A26: =IFERROR(FILTER(Expenses!B5:B200,Expenses!C5:C200=ActiveProject),"") | B26: =IFERROR(FILTER(Expenses!F5:F200,Expenses!C5:C200=ActiveProject),"") | C26: =IFERROR(FILTER(Expenses!G5:G200,Expenses!C5:C200=ActiveProject),"") | D26: =IFERROR(FILTER(Expenses!H5:H200,Expenses!C5:C200=ActiveProject),"") | E26: =IFERROR(FILTER(Expenses!J5:J200,Expenses!C5:C200=ActiveProject),"") | H26: Kitchen | I26: =IFERROR(INDEX(Rooms!J:J,MATCH("RM-01",Rooms!A:A,0)),"") | J26: =IFERROR(INDEX(Rooms!K:K,MATCH("RM-01",Rooms!A:A,0)),0) | K26: =IFERROR(INDEX(Rooms!R:R,MATCH("RM-01",Rooms!A:A,0)),0) | L26: =IF(J26=0,"",K26/J26)
H27: Living Room | I27: =IFERROR(INDEX(Rooms!J:J,MATCH("RM-02",Rooms!A:A,0)),"") | J27: =IFERROR(INDEX(Rooms!K:K,MATCH("RM-02",Rooms!A:A,0)),0) | K27: =IFERROR(INDEX(Rooms!R:R,MATCH("RM-02",Rooms!A:A,0)),0) | L27: =IF(J27=0,"",K27/J27)
H28: Primary Bathroom | I28: =IFERROR(INDEX(Rooms!J:J,MATCH("RM-03",Rooms!A:A,0)),"") | J28: =IFERROR(INDEX(Rooms!K:K,MATCH("RM-03",Rooms!A:A,0)),0) | K28: =IFERROR(INDEX(Rooms!R:R,MATCH("RM-03",Rooms!A:A,0)),0) | L28: =IF(J28=0,"",K28/J28)
H29: Guest Bedroom | I29: =IFERROR(INDEX(Rooms!J:J,MATCH("RM-04",Rooms!A:A,0)),"") | J29: =IFERROR(INDEX(Rooms!K:K,MATCH("RM-04",Rooms!A:A,0)),0) | K29: =IFERROR(INDEX(Rooms!R:R,MATCH("RM-04",Rooms!A:A,0)),0) | L29: =IF(J29=0,"",K29/J29)
H30: Dining Room | I30: =IFERROR(INDEX(Rooms!J:J,MATCH("RM-05",Rooms!A:A,0)),"") | J30: =IFERROR(INDEX(Rooms!K:K,MATCH("RM-05",Rooms!A:A,0)),0) | K30: =IFERROR(INDEX(Rooms!R:R,MATCH("RM-05",Rooms!A:A,0)),0) | L30: =IF(J30=0,"",K30/J30)
H31: Exterior / Garden | I31: =IFERROR(INDEX(Rooms!J:J,MATCH("RM-06",Rooms!A:A,0)),"") | J31: =IFERROR(INDEX(Rooms!K:K,MATCH("RM-06",Rooms!A:A,0)),0) | K31: =IFERROR(INDEX(Rooms!R:R,MATCH("RM-06",Rooms!A:A,0)),0) | L31: =IF(J31=0,"",K31/J31)
H32: Laundry | I32: =IFERROR(INDEX(Rooms!J:J,MATCH("RM-07",Rooms!A:A,0)),"") | J32: =IFERROR(INDEX(Rooms!K:K,MATCH("RM-07",Rooms!A:A,0)),0) | K32: =IFERROR(INDEX(Rooms!R:R,MATCH("RM-07",Rooms!A:A,0)),0) | L32: =IF(J32=0,"",K32/J32)
H33: Entry / Foyer | I33: =IFERROR(INDEX(Rooms!J:J,MATCH("RM-08",Rooms!A:A,0)),"") | J33: =IFERROR(INDEX(Rooms!K:K,MATCH("RM-08",Rooms!A:A,0)),0) | K33: =IFERROR(INDEX(Rooms!R:R,MATCH("RM-08",Rooms!A:A,0)),0) | L33: =IF(J33=0,"",K33/J33)
A36: UPCOMING CONTRACTOR VISITS | H36: QUICK ACTIONS (use the Novality Store menu in Google Sheets)
A37: Date | B37: Event | C37: Owner | D37: Status | H37: + Expense
A38: =IFERROR(FILTER(Calendar!A5:A80,Calendar!A5:A80>=AsOfDate),"") | B38: =IFERROR(FILTER(Calendar!C5:C80,Calendar!A5:A80>=AsOfDate),"") | C38: =IFERROR(FILTER(Calendar!F5:F80,Calendar!A5:A80>=AsOfDate),"") | D38: =IFERROR(FILTER(Calendar!G5:G80,Calendar!A5:A80>=AsOfDate),"") | H38: + Task
H39: Upload photo note
H40: Message contractor
H41: Approve change order
H42: Generate shopping list
A45: AI INSIGHT
A46: =IFERROR(INDEX('AI Insights'!G:G,MATCH(1,('AI Insights'!C:C=ActiveProject)*(('AI Insights'!J:J="New")+('AI Insights'!J:J="In Progress")),0)),"No open AI insights.")
A49: =IFERROR("Recommendation: "&INDEX('AI Insights'!H:H,MATCH(1,('AI Insights'!C:C=ActiveProject)*(('AI Insights'!J:J="New")+('AI Insights'!J:J="In Progress")),0)),"")
A52: NAVIGATION
A53: Projects | C53: Rooms | E53: Design | G53: Budget | I53: Team | K53: Materials
...

Sheet Projects
A1: PROJECTS
A2: All renovation projects · spent/committed roll up from Expenses
A4: Project ID | B4: Property ID | C4: Name | D4: Type | E4: Status | F4: Phase | G4: Start | H4: Target End | I4: Actual End | J4: Budget | K4: Homeowner ID | L4: PM ID | M4: Designer ID | N4: Homeowner Name | O4: Address | P4: Progress | Q4: Notes | R4: Spent | S4: Committed | T4: Remaining | U4: Health
A5: PRJ-001 | B5: PROP-001 | C5: Maplewood Whole-Home Refresh | D5: Whole Home | E5: Active | F5: Construction | G5: 46082 | H5: 46341 | J5: 85000 | K5: HO-001 | L5: PM-001 | M5: DS-001 | N5: Alex Rivera | O5: 1847 Maplewood Drive, Portland, OR | P5: 0.72 | Q5: Kitchen, primary bath, living, guest bedroom, exterior paint, garden path. | R5: =IF($A5="","",SUMIFS(Expenses!$H:$H,Expenses!$C:$C,$A5,Expenses!$J:$J,"Paid")) | S5: =IF($A5="","",SUMIFS(Expenses!$H:$H,Expenses!$C:$C,$A5,Expenses!$J:$J,"Committed")) | T5: =IF($A5="","",$J5-$R5-$S5) | U5: =IF($A5="","",IF($R5+$S5>$J5*(1+OverrunAlert),"Over",IF($R5+$S5>$J5,"Watch","On Track")))
A6: PRJ-002 | B6: PROP-002 | C6: Gorge Cabin Bath Refresh | D6: Bathroom | E6: Planning | F6: Design | G6: 46296 | H6: 46371 | J6: 18500 | K6: HO-001 | L6: PM-001 | M6: DS-001 | N6: Alex Rivera | O6: 88 Ridge Trail, Hood River, OR | P6: 0.12 | Q6: Single bath + vanity lighting. Starts after Maplewood handover. | R6: =IF($A6="","",SUMIFS(Expenses!$H:$H,Expenses!$C:$C,$A6,Expenses!$J:$J,"Paid")) | S6: =IF($A6="","",SUMIFS(Expenses!$H:$H,Expenses!$C:$C,$A6,Expenses!$J:$J,"Committed")) | T6: =IF($A6="","",$J6-$R6-$S6) | U6: =IF($A6="","",IF($R6+$S6>$J6*(1+OverrunAlert),"Over",IF($R6+$S6>$J6,"Watch","On Track")))

Sheet Rooms
A1: ROOMS
A2: Every space is a node in the digital twin
A4: Room ID | B4: Project ID | C4: Room Name | D4: Type | E4: Floor | F4: Length (ft) | G4: Width (ft) | H4: Height (ft) | I4: Condition | J4: Status | K4: Budget | L4: Contractor ID | M4: Design Style | N4: Before Photos | O4: After Photos | P4: Notes | Q4: Area (sf) | R4: Spent | S4: Committed | T4: Remaining | U4: Budget used
A5: RM-01 | B5: PRJ-001 | C5: Kitchen | D5: Kitchen | E5: 1 | F5: 16 | G5: 12.5 | H5: 9 | I5: Fair | J5: In Progress | K5: 32000 | L5: CTR-001 | M5: Modern | N5: drive/photos/kitchen-before | O5: drive/photos/kitchen-wip | P5: Load-bearing wall stays. Island added. | Q5: =IF($A5="","",ROUND($F5*$G5,1)) | R5: =IF($A5="","",SUMIFS(Expenses!$H:$H,Expenses!$D:$D,$A5,Expenses!$J:$J,"Paid")) | S5: =IF($A5="","",SUMIFS(Expenses!$H:$H,Expenses!$D:$D,$A5,Expenses!$J:$J,"Committed")) | T5: =IF($A5="","",$K5-$R5-$S5) | U5: =IF(OR($A5="",$K5=0),"",($R5+$S5)/$K5)
A6: RM-02 | B6: PRJ-001 | C6: Living Room | D6: Living Room | E6: 1 | F6: 20 | G6: 15 | H6: 9.5 | I6: Good | J6: In Progress | K6: 12500 | L6: CTR-006 | M6: Scandinavian | N6: drive/photos/living-before | P6: White oak floors continue from kitchen. | Q6: =IF($A6="","",ROUND($F6*$G6,1)) | R6: =IF($A6="","",SUMIFS(Expenses!$H:$H,Expenses!$D:$D,$A6,Expenses!$J:$J,"Paid")) | S6: =IF($A6="","",SUMIFS(Expenses!$H:$H,Expenses!$D:$D,$A6,Expenses!$J:$J,"Committed")) | T6: =IF($A6="","",$K6-$R6-$S6) | U6: =IF(OR($A6="",$K6=0),"",($R6+$S6)/$K6)
A7: RM-03 | B7: PRJ-001 | C7: Primary Bathroom | D7: Primary Bathroom | E7: 2 | F7: 10 | G7: 8 | H7: 8.5 | I7: Poor | J7: Punch List | K7: 18500 | L7: CTR-004 | M7: Luxury | N7: drive/photos/bath-before | O7: drive/photos/bath-after-draft | P7: Heated floor. Porcelain in lieu of marble. | Q7: =IF($A7="","",ROUND($F7*$G7,1)) | R7: =IF($A7="","",SUMIFS(Expenses!$H:$H,Expenses!$D:$D,$A7,Expenses!$J:$J,"Paid")) | S7: =IF($A7="","",SUMIFS(Expenses!$H:$H,Expenses!$D:$D,$A7,Expenses!$J:$J,"Committed")) | T7: =IF($A7="","",$K7-$R7-$S7) | U7: =IF(OR($A7="",$K7=0),"",($R7+$S7)/$K7)
A8: RM-04 | B8: PRJ-001 | C8: Guest Bedroom | D8: Bedroom | E8: 2 | F8: 12 | G8: 11 | H8: 8.5 | I8: Fair | J8: Design | K8: 6200 | L8: CTR-005 | M8: Minimal | N8: drive/photos/guest-before | P8: Paint, lighting, built-in wardrobe. | Q8: =IF($A8="","",ROUND($F8*$G8,1)) | R8: =IF($A8="","",SUMIFS(Expenses!$H:$H,Expenses!$D:$D,$A8,Expenses!$J:$J,"Paid")) | S8: =IF($A8="","",SUMIFS(Expenses!$H:$H,Expenses!$D:$D,$A8,Expenses!$J:$J,"Committed")) | T8: =IF($A8="","",$K8-$R8-$S8) | U8: =IF(OR($A8="",$K8=0),"",($R8+$S8)/$K8)
A9: RM-05 | B9: PRJ-001 | C9: Dining Room | D9: Dining Room | E9: 1 | F9: 13 | G9: 11 | H9: 9.5 | I9: Good | J9: In Progress | K9: 4800 | L9: CTR-005 | M9: Transitional | N9: drive/photos/dining-before | P9: Sconce pair + plaster repair. | Q9: =IF($A9="","",ROUND($F9*$G9,1)) | R9: =IF($A9="","",SUMIFS(Expenses!$H:$H,Expenses!$D:$D,$A9,Expenses!$J:$J,"Paid")) | S9: =IF($A9="","",SUMIFS(Expenses!$H:$H,Expenses!$D:$D,$A9,Expenses!$J:$J,"Committed")) | T9: =IF($A9="","",$K9-$R9-$S9) | U9: =IF(OR($A9="",$K9=0),"",($R9+$S9)/$K9)
A10: RM-06 | B10: PRJ-001 | C10: Exterior / Garden | D10: Exterior | E10: 0 | F10: 40 | G10: 22 | H10: 0 | I10: Fair | J10: Not Started | K10: 7400 | L10: CTR-010 | M10: Traditional | N10: drive/photos/exterior-before | P10: Front path, porch stain, lighting. | Q10: =IF($A10="","",ROUND($F10*$G10,1)) | R10: =IF($A10="","",SUMIFS(Expenses!$H:$H,Expenses!$D:$D,$A10,Expenses!$J:$J,"Paid")) | S10: =IF($A10="","",SUMIFS(Expenses!$H:$H,Expenses!$D:$D,$A10,Expenses!$J:$J,"Committed")) | T10: =IF($A10="","",$K10-$R10-$S10) | U10: =IF(OR($A10="",$K10=0),"",($R10+$S10)/$K10)
A11: RM-07 | B11: PRJ-001 | C11: Laundry | D11: Laundry | E11: 1 | F11: 8 | G11: 6 | H11: 8.5 | I11: Fair | J11: Complete | K11: 2100 | L11: CTR-003 | M11: Minimal | N11: drive/photos/laundry-before | O11: drive/photos/laundry-after | P11: Utility sink and tile splash. | Q11: =IF($A11="","",ROUND($F11*$G11,1)) | R11: =IF($A11="","",SUMIFS(Expenses!$H:$H,Expenses!$D:$D,$A11,Expenses!$J:$J,"Paid")) | S11: =IF($A11="","",SUMIFS(Expenses!$H:$H,Expenses!$D:$D,$A11,Expenses!$J:$J,"Committed")) | T11: =IF($A11="","",$K11-$R11-$S11) | U11: =IF(OR($A11="",$K11=0),"",($R11+$S11)/$K11)
A12: RM-08 | B12: PRJ-001 | C12: Entry / Foyer | D12: Entry / Foyer | E12: 1 | F12: 8 | G12: 7 | H12: 9.5 | I12: Good | J12: In Progress | K12: 1500 | L12: CTR-005 | M12: Transitional | N12: drive/photos/entry-before | P12: Bench, hook rail, paint. | Q12: =IF($A12="","",ROUND($F12*$G12,1)) | R12: =IF($A12="","",SUMIFS(Expenses!$H:$H,Expenses!$D:$D,$A12,Expenses!$J:$J,"Paid")) | S12: =IF($A12="","",SUMIFS(Expenses!$H:$H,Expenses!$D:$D,$A12,Expenses!$J:$J,"Committed")) | T12: =IF($A12="","",$K12-$R12-$S12) | U12: =IF(OR($A12="",$K12=0),"",($R12+$S12)/$K12)
A13: RM-09 | B13: PRJ-002 | C13: Cabin Bathroom | D13: Bathroom | E13: 1 | F13: 8 | G13: 6.5 | H13: 8 | I13: Poor | J13: Design | K13: 18500 | L13: CTR-004 | M13: Scandinavian | N13: drive/photos/cabin-bath-before | P13: Full gut. Starts October. | Q13: =IF($A13="","",ROUND($F13*$G13,1)) | R13: =IF($A13="","",SUMIFS(Expenses!$H:$H,Expenses!$D:$D,$A13,Expenses!$J:$J,"Paid")) | S13: =IF($A13="","",SUMIFS(Expenses!$H:$H,Expenses!$D:$D,$A13,Expenses!$J:$J,"Committed")) | T13: =IF($A13="","",$K13-$R13-$S13) | U13: =IF(OR($A13="",$K13=0),"",($R13+$S13)/$K13)

Sheet Design Studio
A1: DESIGN STUDIO
A2: Mood boards, palettes, materials, 2D/3D, AI concepts · style presets included
A4: Design ID | B4: Project ID | C4: Room ID | D4: Item Type | E4: Name | F4: Style | G4: Brand | H4: Color Hex | I4: Link / File | J4: Status | K4: Cost Est. | L4: AI Suggested | M4: Notes
A5: DSN-001 | B5: PRJ-001 | C5: RM-01 | D5: Mood Board | E5: Kitchen — warm modern | F5: Modern | H5: #16352F | I5: drive/mood/kitchen-01 | J5: Approved | K5: 0 | L5: No | M5: Forest + sand + terracotta. Brass hardware.
A6: DSN-002 | B6: PRJ-001 | C6: RM-01 | D6: Color Palette | E6: Kitchen palette v3 | F6: Modern | G6: Farrow & Ball | H6: #E8DDCB | I6: drive/palette/kitchen | J6: Approved | K6: 0 | L6: Yes | M6: AI suggested dropping cool gray for sand.
A7: DSN-003 | B7: PRJ-001 | C7: RM-01 | D7: Cabinetry | E7: Shaker, painted sage | F7: Modern | G7: Cascade | H7: #719B7A | I7: drive/cabs/shaker-sage | J7: Approved | K7: 14800 | L7: No | M7: Inset doors, walnut island.
A8: DSN-004 | B8: PRJ-001 | C8: RM-01 | D8: Flooring | E8: White oak 7in | F8: Scandinavian | G8: Timberline | H8: #D4C6AE | I8: drive/floor/oak | J8: Installed | K8: 4200 | L8: No | M8: Continues into living + dining.
A9: DSN-005 | B9: PRJ-001 | C9: RM-01 | D9: Lighting | E9: Aged brass pendants x3 | F9: Luxury | G9: BrightPath | H9: #C86B4A | I9: drive/light/island | J9: Ordered | K9: 890 | L9: No | M9: Dimmer on island circuit.
A10: DSN-006 | B10: PRJ-001 | C10: RM-03 | D10: Material Board | E10: Bath — porcelain in lieu of marble | F10: Luxury | G10: Heritage | H10: #F8F6F1 | I10: drive/bath/materials | J10: Approved | K10: 0 | L10: Yes | M10: AI: porcelain saves ~18% vs marble.
A11: DSN-007 | B11: PRJ-001 | C11: RM-03 | D11: AI Concept | E11: Primary bath — spa luxury | F11: Luxury | I11: drive/ai/bath-luxury | J11: Accepted | K11: 0 | L11: Yes | M11: Before/after concept set.
A12: DSN-008 | B12: PRJ-001 | C12: RM-02 | D12: Mood Board | E12: Living — Scandinavian calm | F12: Scandinavian | H12: #E8DDCB | I12: drive/mood/living | J12: Approved | K12: 0 | L12: No | M12: Linen, oak, charcoal textiles.
A13: DSN-009 | B13: PRJ-001 | C13: RM-02 | D13: Furniture | E13: Modular sofa + oak table | F13: Scandinavian | G13: Article | H13: #202522 | I13: drive/furn/living | J13: Quoted | K13: 3400 | L13: No | M13: Lead time 6 weeks — order by Sep 1.
A14: DSN-010 | B14: PRJ-001 | C14: RM-04 | D14: Color Palette | E14: Guest — clay + linen | F14: Minimal | G14: Benjamin Moore | H14: #C86B4A | I14: drive/palette/guest | J14: In Review | K14: 0 | L14: Yes | M14: Two accent options pending Alex.
A15: DSN-011 | B15: PRJ-001 | C15: RM-01 | D15: 2D Floor Plan | E15: Kitchen layout v4 | F15: Modern | G15: Luna | I15: drive/plans/kitchen-v4 | J15: Approved | K15: 0 | L15: No | M15: Island 8ft. Fridge wall flipped.
A16: DSN-012 | B16: PRJ-001 | C16: RM-01 | D16: 3D Visualization | E16: Kitchen dusk render | F16: Modern | G16: Luna | I16: drive/3d/kitchen-dusk | J16: Approved | K16: 0 | L16: Yes | M16: AI lighting study included.
A17: DSN-013 | B17: PRJ-002 | C17: RM-09 | D17: Mood Board | E17: Cabin bath — Japandi | F17: Japandi | H17: #16352F | I17: drive/mood/cabin | J17: Draft | K17: 0 | L17: Yes | M17: Cedar, plaster, black fixtures.

Sheet AI Insights
A1: AI INSIGHTS
A2: Renovation assistant · budget, materials, schedule, contractor comparison, photo analysis
A4: Insight ID | B4: Date | C4: Project ID | D4: Room ID | E4: Category | F4: Severity | G4: Insight | H4: Recommendation | I4: Est. Impact $ | J4: Status | K4: Action Taken
A5: AI-001 | B5: 46254 | C5: PRJ-001 | D5: RM-01 | E5: Budget | F5: Warning | G5: Kitchen renovation is currently 12% over the planned budget. | H5: Switch remaining stone from marble to porcelain slab on the island only; keep quartz on perimeter. | I5: 2100 | J5: Accepted | K5: Quote requested from Heritage Tile
A6: AI-002 | B6: 46252 | C6: PRJ-001 | D6: RM-03 | E6: Materials | F6: Opportunity | G6: Porcelain tile alternative identified for primary bath floor. | H6: Heritage porcelain (SKU HT-8841) matches the approved palette and saves ~18% versus marble. | I6: 1640 | J6: Resolved | K6: Material swapped. Installed.
A7: AI-003 | B7: 46256 | C7: PRJ-001 | D7: RM-01 | E7: Schedule | F7: Warning | G7: Cabinet installation is on the critical path and hardware is still in transit. | H7: Confirm hardware ETA. If later than Aug 27, install doors without pulls and return for hardware day. | I7: 0 | J7: In Progress | K7: Maya tracking shipment
A8: AI-004 | B8: 46249 | C8: PRJ-001 | E8: Contractor | F8: Info | G8: Three lighting bids received. Spread is 22%. | H8: BrightPath is mid-price with the highest communication score. Accept unless value-engineering fixtures. | I8: 340 | J8: Accepted | K8: BrightPath awarded
A9: AI-005 | B9: 46257 | C9: PRJ-001 | D9: RM-06 | E9: Risk | F9: Critical | G9: Project contingency has fallen to 9.4%, below the 10% threshold. | H9: Freeze non-critical exterior extras (water feature) until kitchen close-out. | I9: 1800 | J9: New
A10: AI-006 | B10: 46244 | C10: PRJ-001 | D10: RM-02 | E10: Design | F10: Opportunity | G10: Room photo analysis: north-facing living room reads cool and dim after 4pm. | H10: Specify 2700K lamps, add floor lamp at north corner, keep walls in Warm Sand not cool gray. | I10: 0 | J10: Resolved | K10: Palette updated
A11: AI-007 | B11: 46255 | C11: PRJ-001 | E11: Procurement | F11: Warning | G11: White oak stair nosing is backordered 11 days. | H11: Use matching leftover plank with site-cut nosing, or delay living-room furniture delivery. | I11: 0 | J11: Accepted | K11: Site-cut nosing approved
A12: AI-008 | B12: 46258 | C12: PRJ-001 | E12: Prediction | F12: Info | G12: Likely completion date given current float: 12 Nov 2026 (3 days ahead of target). | H12: Protect flooring cure time. Do not accelerate furniture move-in before Oct 20. | I12: 0 | J12: New

Sheet Budget
A1: BUDGET
A2: Category + room budgets · spent/committed live from Expenses
A4: Line ID | B4: Project ID | C4: Room ID | D4: Category | E4: Subcategory | F4: Planned | G4: Spent (Paid) | H4: Committed | I4: Remaining | J4: Variance | K4: Variance % | L4: Alert
A5: BL-001 | B5: PRJ-001 | C5: RM-01 | D5: Materials | E5: Cabinetry & hardware | F5: 14800 | G5: =IF($A5="","",IF($C5="",SUMIFS(Expenses!$H:$H,Expenses!$C:$C,$B5,Expenses!$E:$E,$D5,Expenses!$J:$J,"Paid"),SUMIFS(Expenses!$H:$H,Expenses!$C:$C,$B5,Expenses!$D:$D,$C5,Expenses!$E:$E,$D5,Expenses!$J:$J,"Paid"))) | H5: =IF($A5="","",IF($C5="",SUMIFS(Expenses!$H:$H,Expenses!$C:$C,$B5,Expenses!$E:$E,$D5,Expenses!$J:$J,"Committed"),SUMIFS(Expenses!$H:$H,Expenses!$C:$C,$B5,Expenses!$D:$D,$C5,Expenses!$E:$E,$D5,Expenses!$J:$J,"Committed"))) | I5: =IF($A5="","",$F5-$G5-$H5) | J5: =IF($A5="","",$F5-($G5+$H5)) | K5: =IF(OR($A5="",$F5=0),"",($G5+$H5-$F5)/$F5) | L5: =IF($A5="","",IF($F5=0,"",IF(($G5+$H5)>$F5*(1+OverrunAlert),"Over",IF(($G5+$H5)>$F5,"Watch",IF(($G5+$H5)<$F5*0.85,"Under","On Track")))))
A6: BL-002 | B6: PRJ-001 | C6: RM-01 | D6: Materials | E6: Counters & backsplash | F6: 6200 | G6: =IF($A6="","",IF($C6="",SUMIFS(Expenses!$H:$H,Expenses!$C:$C,$B6,Expenses!$E:$E,$D6,Expenses!$J:$J,"Paid"),SUMIFS(Expenses!$H:$H,Expenses!$C:$C,$B6,Expenses!$D:$D,$C6,Expenses!$E:$E,$D6,Expenses!$J:$J,"Paid"))) | H6: =IF($A6="","",IF($C6="",SUMIFS(Expenses!$H:$H,Expenses!$C:$C,$B6,Expenses!$E:$E,$D6,Expenses!$J:$J,"Committed"),SUMIFS(Expenses!$H:$H,Expenses!$C:$C,$B6,Expenses!$D:$D,$C6,Expenses!$E:$E,$D6,Expenses!$J:$J,"Committed"))) | I6: =IF($A6="","",$F6-$G6-$H6) | J6: =IF($A6="","",$F6-($G6+$H6)) | K6: =IF(OR($A6="",$F6=0),"",($G6+$H6-$F6)/$F6) | L6: =IF($A6="","",IF($F6=0,"",IF(($G6+$H6)>$F6*(1+OverrunAlert),"Over",IF(($G6+$H6)>$F6,"Watch",IF(($G6+$H6)<$F6*0.85,"Under","On Track")))))
A7: BL-003 | B7: PRJ-001 | C7: RM-01 | D7: Materials | E7: Appliances | F7: 5400 | G7: =IF($A7="","",IF($C7="",SUMIFS(Expenses!$H:$H,Expenses!$C:$C,$B7,Expenses!$E:$E,$D7,Expenses!$J:$J,"Paid"),SUMIFS(Expenses!$H:$H,Expenses!$C:$C,$B7,Expenses!$D:$D,$C7,Expenses!$E:$E,$D7,Expenses!$J:$J,"Paid"))) | H7: =IF($A7="","",IF($C7="",SUMIFS(Expenses!$H:$H,Expenses!$C:$C,$B7,Expenses!$E:$E,$D7,Expenses!$J:$J,"Committed"),SUMIFS(Expenses!$H:$H,Expenses!$C:$C,$B7,Expenses!$D:$D,$C7,Expenses!$E:$E,$D7,Expenses!$J:$J,"Committed"))) | I7: =IF($A7="","",$F7-$G7-$H7) | J7: =IF($A7="","",$F7-($G7+$H7)) | K7: =IF(OR($A7="",$F7=0),"",($G7+$H7-$F7)/$F7) | L7: =IF($A7="","",IF($F7=0,"",IF(($G7+$H7)>$F7*(1+OverrunAlert),"Over",IF(($G7+$H7)>$F7,"Watch",IF(($G7+$H7)<$F7*0.85,"Under","On Track")))))
A8: BL-004 | B8: PRJ-001 | C8: RM-01 | D8: Labor | E8: Cabinet install + finish carpentry | F8: 3600 | G8: =IF($A8="","",IF($C8="",SUMIFS(Expenses!$H:$H,Expenses!$C:$C,$B8,Expenses!$E:$E,$D8,Expenses!$J:$J,"Paid"),SUMIFS(Expenses!$H:$H,Expenses!$C:$C,$B8,Expenses!$D:$D,$C8,Expenses!$E:$E,$D8,Expenses!$J:$J,"Paid"))) | H8: =IF($A8="","",IF($C8="",SUMIFS(Expenses!$H:$H,Expenses!$C:$C,$B8,Expenses!$E:$E,$D8,Expenses!$J:$J,"Committed"),SUMIFS(Expenses!$H:$H,Expenses!$C:$C,$B8,Expenses!$D:$D,$C8,Expenses!$E:$E,$D8,Expenses!$J:$J,"Committed"))) | I8: =IF($A8="","",$F8-$G8-$H8) | J8: =IF($A8="","",$F8-($G8+$H8)) | K8: =IF(OR($A8="",$F8=0),"",($G8+$H8-$F8)/$F8) | L8: =IF($A8="","",IF($F8=0,"",IF(($G8+$H8)>$F8*(1+OverrunAlert),"Over",IF(($G8+$H8)>$F8,"Watch",IF(($G8+$H8)<$F8*0.85,"Under","On Track")))))
A9: BL-005 | B9: PRJ-001 | C9: RM-01 | D9: Labor | E9: Plumbing relocate | F9: 1400 | G9: =IF($A9="","",IF($C9="",SUMIFS(Expenses!$H:$H,Expenses!$C:$C,$B9,Expenses!$E:$E,$D9,Expenses!$J:$J,"Paid"),SUMIFS(Expenses!$H:$H,Expenses!$C:$C,$B9,Expenses!$D:$D,$C9,Expenses!$E:$E,$D9,Expenses!$J:$J,"Paid"))) | H9: =IF($A9="","",IF($C9="",SUMIFS(Expenses!$H:$H,Expenses!$C:$C,$B9,Expenses!$E:$E,$D9,Expenses!$J:$J,"Committed"),SUMIFS(Expenses!$H:$H,Expenses!$C:$C,$B9,Expenses!$D:$D,$C9,Expenses!$E:$E,$D9,Expenses!$J:$J,"Committed"))) | I9: =IF($A9="","",$F9-$G9-$H9) | J9: =IF($A9="","",$F9-($G9+$H9)) | K9: =IF(OR($A9="",$F9=0),"",($G9+$H9-$F9)/$F9) | L9: =IF($A9="","",IF($F9=0,"",IF(($G9+$H9)>$F9*(1+OverrunAlert),"Over",IF(($G9+$H9)>$F9,"Watch",IF(($G9+$H9)<$F9*0.85,"Under","On Track")))))
A10: BL-006 | B10: PRJ-001 | C10: RM-01 | D10: Labor | E10: Electrical / lighting | F10: 600 | G10: =IF($A10="","",IF($C10="",SUMIFS(Expenses!$H:$H,Expenses!$C:$C,$B10,Expenses!$E:$E,$D10,Expenses!$J:$J,"Paid"),SUMIFS(Expenses!$H:$H,Expenses!$C:$C,$B10,Expenses!$D:$D,$C10,Expenses!$E:$E,$D10,Expenses!$J:$J,"Paid"))) | H10: =IF($A10="","",IF($C10="",SUMIFS(Expenses!$H:$H,Expenses!$C:$C,$B10,Expenses!$E:$E,$D10,Expenses!$J:$J,"Committed"),SUMIFS(Expenses!$H:$H,Expenses!$C:$C,$B10,Expenses!$D:$D,$C10,Expenses!$E:$E,$D10,Expenses!$J:$J,"Committed"))) | I10: =IF($A10="","",$F10-$G10-$H10) | J10: =IF($A10="","",$F10-($G10+$H10)) | K10: =IF(OR($A10="",$F10=0),"",($G10+$H10-$F10)/$F10) | L10: =IF($A10="","",IF($F10=0,"",IF(($G10+$H10)>$F10*(1+OverrunAlert),"Over",IF(($G10+$H10)>$F10,"Watch",IF(($G10+$H10)<$F10*0.85,"Under","On Track")))))
A11: BL-007 | B11: PRJ-001 | C11: RM-02 | D11: Materials | E11: White oak flooring (share) | F11: 2800 | G11: =IF($A11="","",IF($C11="",SUMIFS(Expenses!$H:$H,Expenses!$C:$C,$B11,Expenses!$E:$E,$D11,Expenses!$J:$J,"Paid"),SUMIFS(Expenses!$H:$H,Expenses!$C:$C,$B11,Expenses!$D:$D,$C11,Expenses!$E:$E,$D11,Expenses!$J:$J,"Paid"))) | H11: =IF($A11="","",IF($C11="",SUMIFS(Expenses!$H:$H,Expenses!$C:$C,$B11,Expenses!$E:$E,$D11,Expenses!$J:$J,"Committed"),SUMIFS(Expenses!$H:$H,Expenses!$C:$C,$B11,Expenses!$D:$D,$C11,Expenses!$E:$E,$D11,Expenses!$J:$J,"Committed"))) | I11: =IF($A11="","",$F11-$G11-$H11) | J11: =IF($A11="","",$F11-($G11+$H11)) | K11: =IF(OR($A11="",$F11=0),"",($G11+$H11-$F11)/$F11) | L11: =IF($A11="","",IF($F11=0,"",IF(($G11+$H11)>$F11*(1+OverrunAlert),"Over",IF(($G11+$H11)>$F11,"Watch",IF(($G11+$H11)<$F11*0.85,"Under","On Track")))))
A12: BL-008 | B12: PRJ-001 | C12: RM-02 | D12: Labor | E12: Floor install + finish | F12: 2200 | G12: =IF($A12="","",IF($C12="",SUMIFS(Expenses!$H:$H,Expenses!$C:$C,$B12,Expenses!$E:$E,$D12,Expenses!$J:$J,"Paid"),SUMIFS(Expenses!$H:$H,Expenses!$C:$C,$B12,Expenses!$D:$D,$C12,Expenses!$E:$E,$D12,Expenses!$J:$J,"Paid"))) | H12: =IF($A12="","",IF($C12="",SUMIFS(Expenses!$H:$H,Expenses!$C:$C,$B12,Expenses!$E:$E,$D12,Expenses!$J:$J,"Committed"),SUMIFS(Expenses!$H:$H,Expenses!$C:$C,$B12,Expenses!$D:$D,$C12,Expenses!$E:$E,$D12,Expenses!$J:$J,"Committed"))) | I12: =IF($A12="","",$F12-$G12-$H12) | J12: =IF($A12="","",$F12-($G12+$H12)) | K12: =IF(OR($A12="",$F12=0),"",($G12+$H12-$F12)/$F12) | L12: =IF($A12="","",IF($F12=0,"",IF(($G12+$H12)>$F12*(1+OverrunAlert),"Over",IF(($G12+$H12)>$F12,"Watch",IF(($G12+$H12)<$F12*0.85,"Under","On Track")))))
A13: BL-009 | B13: PRJ-001 | C13: RM-02 | D13: Furniture | E13: Sofa, table, lighting | F13: 4200 | G13: =IF($A13="","",IF($C13="",SUMIFS(Expenses!$H:$H,Expenses!$C:$C,$B13,Expenses!$E:$E,$D13,Expenses!$J:$J,"Paid"),SUMIFS(Expenses!$H:$H,Expenses!$C:$C,$B13,Expenses!$D:$D,$C13,Expenses!$E:$E,$D13,Expenses!$J:$J,"Paid"))) | H13: =IF($A13="","",IF($C13="",SUMIFS(Expenses!$H:$H,Expenses!$C:$C,$B13,Expenses!$E:$E,$D13,Expenses!$J:$J,"Committed"),SUMIFS(Expenses!$H:$H,Expenses!$C:$C,$B13,Expenses!$D:$D,$C13,Expenses!$E:$E,$D13,Expenses!$J:$J,"Committed"))) | I13: =IF($A13="","",$F13-$G13-$H13) | J13: =IF($A13="","",$F13-($G13+$H13)) | K13: =IF(OR($A13="",$F13=0),"",($G13+$H13-$F13)/$F13) | L13: =IF($A13="","",IF($F13=0,"",IF(($G13+$H13)>$F13*(1+OverrunAlert),"Over",IF(($G13+$H13)>$F13,"Watch",IF(($G13+$H13)<$F13*0.85,"Under","On Track")))))
A14: BL-010 | B14: PRJ-001 | C14: RM-02 | D14: Materials | E14: Paint & plaster | F14: 900 | G14: =IF($A14="","",IF($C14="",SUMIFS(Expenses!$H:$H,Expenses!$C:$C,$B14,Expenses!$E:$E,$D14,Expenses!$J:$J,"Paid"),SUMIFS(Expenses!$H:$H,Expenses!$C:$C,$B14,Expenses!$D:$D,$C14,Expenses!$E:$E,$D14,Expenses!$J:$J,"Paid"))) | H14: =IF($A14="","",IF($C14="",SUMIFS(Expenses!$H:$H,Expenses!$C:$C,$B14,Expenses!$E:$E,$D14,Expenses!$J:$J,"Committed"),SUMIFS(Expenses!$H:$H,Expenses!$C:$C,$B14,Expenses!$D:$D,$C14,Expenses!$E:$E,$D14,Expenses!$J:$J,"Committed"))) | I14: =IF($A14="","",$F14-$G14-$H14) | J14: =IF($A14="","",$F14-($G14+$H14)) | K14: =IF(OR($A14="",$F14=0),"",($G14+$H14-$F14)/$F14) | L14: =IF($A14="","",IF($F14=0,"",IF(($G14+$H14)>$F14*(1+OverrunAlert),"Over",IF(($G14+$H14)>$F14,"Watch",IF(($G14+$H14)<$F14*0.85,"Under","On Track")))))
A15: BL-011 | B15: PRJ-001 | C15: RM-02 | D15: Labor | E15: Paint labor | F15: 1400 | G15: =IF($A15="","",IF($C15="",SUMIFS(Expenses!$H:$H,Expenses!$C:$C,$B15,Expenses!$E:$E,$D15,Expenses!$J:$J,"Paid"),SUMIFS(Expenses!$H:$H,Expenses!$C:$C,$B15,Expenses!$D:$D,$C15,Expenses!$E:$E,$D15,Expenses!$J:$J,"Paid"))) | H15: =IF($A15="","",IF($C15="",SUMIFS(Expenses!$H:$H,Expenses!$C:$C,$B15,Expenses!$E:$E,$D15,Expenses!$J:$J,"Committed"),SUMIFS(Expenses!$H:$H,Expenses!$C:$C,$B15,Expenses!$D:$D,$C15,Expenses!$E:$E,$D15,Expenses!$J:$J,"Committed"))) | I15: =IF($A15="","",$F15-$G15-$H15) | J15: =IF($A15="","",$F15-($G15+$H15)) | K15: =IF(OR($A15="",$F15=0),"",($G15+$H15-$F15)/$F15) | L15: =IF($A15="","",IF($F15=0,"",IF(($G15+$H15)>$F15*(1+OverrunAlert),"Over",IF(($G15+$H15)>$F15,"Watch",IF(($G15+$H15)<$F15*0.85,"Under","On Track")))))
A16: BL-012 | B16: PRJ-001 | C16: RM-03 | D16: Materials | E16: Tile, fixtures, vanity | F16: 9200 | G16: =IF($A16="","",IF($C16="",SUMIFS(Expenses!$H:$H,Expenses!$C:$C,$B16,Expenses!$E:$E,$D16,Expenses!$J:$J,"Paid"),SUMIFS(Expenses!$H:$H,Expenses!$C:$C,$B16,Expenses!$D:$D,$C16,Expenses!$E:$E,$D16,Expenses!$J:$J,"Paid"))) | H16: =IF($A16="","",IF($C16="",SUMIFS(Expenses!$H:$H,Expenses!$C:$C,$B16,Expenses!$E:$E,$D16,Expenses!$J:$J,"Committed"),SUMIFS(Expenses!$H:$H,Expenses!$C:$C,$B16,Expenses!$D:$D,$C16,Expenses!$E:$E,$D16,Expenses!$J:$J,"Committed"))) | I16: =IF($A16="","",$F16-$G16-$H16) | J16: =IF($A16="","",$F16-($G16+$H16)) | K16: =IF(OR($A16="",$F16=0),"",($G16+$H16-$F16)/$F16) | L16: =IF($A16="","",IF($F16=0,"",IF(($G16+$H16)>$F16*(1+OverrunAlert),"Over",IF(($G16+$H16)>$F16,"Watch",IF(($G16+$H16)<$F16*0.85,"Under","On Track")))))
... A30: BL-026 | B30: PRJ-001 | C30: RM-08 | D30: Labor | E30: Carpentry + paint | F30: 800 | G30: =IF($A30="","",IF($C30="",SUMIFS(Expenses!$H:$H,Expenses!$C:$C,$B30,Expenses!$E:$E,$D30,Expenses!$J:$J,"Paid"),SUMIFS(Expenses!$H:$H,Expenses!$C:$C,$B30,Expenses!$D:$D,$C30,Expenses!$E:$E,$D30,Expenses!$J:$J,"Paid"))) | H30: =IF($A30="","",IF($C30="",SUMIFS(Expenses!$H:$H,Expenses!$C:$C,$B30,Expenses!$E:$E,$D30,Expenses!$J:$J,"Committed"),SUMIFS(Expenses!$H:$H,Expenses!$C:$C,$B30,Expenses!$D:$D,$C30,Expenses!$E:$E,$D30,Expenses!$J:$J,"Committed"))) | I30: =IF($A30="","",$F30-$G30-$H30) | J30: =IF($A30="","",$F30-($G30+$H30)) | K30: =IF(OR($A30="",$F30=0),"",($G30+$H30-$F30)/$F30) | L30: =IF($A30="","",IF($F30=0,"",IF(($G30+$H30)>$F30*(1+OverrunAlert),"Over",IF(($G30+$H30)>$F30,"Watch",IF(($G30+$H30)<$F30*0.85,"Under","On Track")))))
A31: BL-027 | B31: PRJ-001 | D31: Design | E31: Luna Interiors retainer + hours | F31: 4800 | G31: =IF($A31="","",IF($C31="",SUMIFS(Expenses!$H:$H,Expenses!$C:$C,$B31,Expenses!$E:$E,$D31,Expenses!$J:$J,"Paid"),SUMIFS(Expenses!$H:$H,Expenses!$C:$C,$B31,Expenses!$D:$D,$C31,Expenses!$E:$E,$D31,Expenses!$J:$J,"Paid"))) | H31: =IF($A31="","",IF($C31="",SUMIFS(Expenses!$H:$H,Expenses!$C:$C,$B31,Expenses!$E:$E,$D31,Expenses!$J:$J,"Committed"),SUMIFS(Expenses!$H:$H,Expenses!$C:$C,$B31,Expenses!$D:$D,$C31,Expenses!$E:$E,$D31,Expenses!$J:$J,"Committed"))) | I31: =IF($A31="","",$F31-$G31-$H31) | J31: =IF($A31="","",$F31-($G31+$H31)) | K31: =IF(OR($A31="",$F31=0),"",($G31+$H31-$F31)/$F31) | L31: =IF($A31="","",IF($F31=0,"",IF(($G31+$H31)>$F31*(1+OverrunAlert),"Over",IF(($G31+$H31)>$F31,"Watch",IF(($G31+$H31)<$F31*0.85,"Under","On Track")))))
A32: BL-028 | B32: PRJ-001 | D32: Permits | E32: Building, electrical, plumbing | F32: 1850 | G32: =IF($A32="","",IF($C32="",SUMIFS(Expenses!$H:$H,Expenses!$C:$C,$B32,Expenses!$E:$E,$D32,Expenses!$J:$J,"Paid"),SUMIFS(Expenses!$H:$H,Expenses!$C:$C,$B32,Expenses!$D:$D,$C32,Expenses!$E:$E,$D32,Expenses!$J:$J,"Paid"))) | H32: =IF($A32="","",IF($C32="",SUMIFS(Expenses!$H:$H,Expenses!$C:$C,$B32,Expenses!$E:$E,$D32,Expenses!$J:$J,"Committed"),SUMIFS(Expenses!$H:$H,Expenses!$C:$C,$B32,Expenses!$D:$D,$C32,Expenses!$E:$E,$D32,Expenses!$J:$J,"Committed"))) | I32: =IF($A32="","",$F32-$G32-$H32) | J32: =IF($A32="","",$F32-($G32+$H32)) | K32: =IF(OR($A32="",$F32=0),"",($G32+$H32-$F32)/$F32) | L32: =IF($A32="","",IF($F32=0,"",IF(($G32+$H32)>$F32*(1+OverrunAlert),"Over",IF(($G32+$H32)>$F32,"Watch",IF(($G32+$H32)<$F32*0.85,"Under","On Track")))))
A33: BL-029 | B33: PRJ-001 | D33: Delivery | E33: Freight & white-glove | F33: 900 | G33: =IF($A33="","",IF($C33="",SUMIFS(Expenses!$H:$H,Expenses!$C:$C,$B33,Expenses!$E:$E,$D33,Expenses!$J:$J,"Paid"),SUMIFS(Expenses!$H:$H,Expenses!$C:$C,$B33,Expenses!$D:$D,$C33,Expenses!$E:$E,$D33,Expenses!$J:$J,"Paid"))) | H33: =IF($A33="","",IF($C33="",SUMIFS(Expenses!$H:$H,Expenses!$C:$C,$B33,Expenses!$E:$E,$D33,Expenses!$J:$J,"Committed"),SUMIFS(Expenses!$H:$H,Expenses!$C:$C,$B33,Expenses!$D:$D,$C33,Expenses!$E:$E,$D33,Expenses!$J:$J,"Committed"))) | I33: =IF($A33="","",$F33-$G33-$H33) | J33: =IF($A33="","",$F33-($G33+$H33)) | K33: =IF(OR($A33="",$F33=0),"",($G33+$H33-$F33)/$F33) | L33: =IF($A33="","",IF($F33=0,"",IF(($G33+$H33)>$F33*(1+OverrunAlert),"Over",IF(($G33+$H33)>$F33,"Watch",IF(($G33+$H33)<$F33*0.85,"Under","On Track")))))
A34: BL-030 | B34: PRJ-001 | D34: Inspections | E34: City + independent | F34: 650 | G34: =IF($A34="","",IF($C34="",SUMIFS(Expenses!$H:$H,Expenses!$C:$C,$B34,Expenses!$E:$E,$D34,Expenses!$J:$J,"Paid"),SUMIFS(Expenses!$H:$H,Expenses!$C:$C,$B34,Expenses!$D:$D,$C34,Expenses!$E:$E,$D34,Expenses!$J:$J,"Paid"))) | H34: =IF($A34="","",IF($C34="",SUMIFS(Expenses!$H:$H,Expenses!$C:$C,$B34,Expenses!$E:$E,$D34,Expenses!$J:$J,"Committed"),SUMIFS(Expenses!$H:$H,Expenses!$C:$C,$B34,Expenses!$D:$D,$C34,Expenses!$E:$E,$D34,Expenses!$J:$J,"Committed"))) | I34: =IF($A34="","",$F34-$G34-$H34) | J34: =IF($A34="","",$F34-($G34+$H34)) | K34: =IF(OR($A34="",$F34=0),"",($G34+$H34-$F34)/$F34) | L34: =IF($A34="","",IF($F34=0,"",IF(($G34+$H34)>$F34*(1+OverrunAlert),"Over",IF(($G34+$H34)>$F34,"Watch",IF(($G34+$H34)<$F34*0.85,"Under","On Track")))))
A35: BL-031 | B35: PRJ-001 | D35: Contingency | E35: 10% project reserve | F35: 8500 | G35: =IF($A35="","",IF($C35="",SUMIFS(Expenses!$H:$H,Expenses!$C:$C,$B35,Expenses!$E:$E,$D35,Expenses!$J:$J,"Paid"),SUMIFS(Expenses!$H:$H,Expenses!$C:$C,$B35,Expenses!$D:$D,$C35,Expenses!$E:$E,$D35,Expenses!$J:$J,"Paid"))) | H35: =IF($A35="","",IF($C35="",SUMIFS(Expenses!$H:$H,Expenses!$C:$C,$B35,Expenses!$E:$E,$D35,Expenses!$J:$J,"Committed"),SUMIFS(Expenses!$H:$H,Expenses!$C:$C,$B35,Expenses!$D:$D,$C35,Expenses!$E:$E,$D35,Expenses!$J:$J,"Committed"))) | I35: =IF($A35="","",$F35-$G35-$H35) | J35: =IF($A35="","",$F35-($G35+$H35)) | K35: =IF(OR($A35="",$F35=0),"",($G35+$H35-$F35)/$F35) | L35: =IF($A35="","",IF($F35=0,"",IF(($G35+$H35)>$F35*(1+OverrunAlert),"Over",IF(($G35+$H35)>$F35,"Watch",IF(($G35+$H35)<$F35*0.85,"Under","On Track")))))
A36: BL-032 | B36: PRJ-001 | C36: RM-01 | D36: Labor | E36: Demolition (kitchen share) | F36: 0 | G36: =IF($A36="","",IF($C36="",SUMIFS(Expenses!$H:$H,Expenses!$C:$C,$B36,Expenses!$E:$E,$D36,Expenses!$J:$J,"Paid"),SUMIFS(Expenses!$H:$H,Expenses!$C:$C,$B36,Expenses!$D:$D,$C36,Expenses!$E:$E,$D36,Expenses!$J:$J,"Paid"))) | H36: =IF($A36="","",IF($C36="",SUMIFS(Expenses!$H:$H,Expenses!$C:$C,$B36,Expenses!$E:$E,$D36,Expenses!$J:$J,"Committed"),SUMIFS(Expenses!$H:$H,Expenses!$C:$C,$B36,Expenses!$D:$D,$C36,Expenses!$E:$E,$D36,Expenses!$J:$J,"Committed"))) | I36: =IF($A36="","",$F36-$G36-$H36) | J36: =IF($A36="","",$F36-($G36+$H36)) | K36: =IF(OR($A36="",$F36=0),"",($G36+$H36-$F36)/$F36) | L36: =IF($A36="","",IF($F36=0,"",IF(($G36+$H36)>$F36*(1+OverrunAlert),"Over",IF(($G36+$H36)>$F36,"Watch",IF(($G36+$H36)<$F36*0.85,"Under","On Track")))))
A37: BL-033 | B37: PRJ-001 | D37: Labor | E37: General contractor / PM | F37: 6200 | G37: =IF($A37="","",IF($C37="",SUMIFS(Expenses!$H:$H,Expenses!$C:$C,$B37,Expenses!$E:$E,$D37,Expenses!$J:$J,"Paid"),SUMIFS(Expenses!$H:$H,Expenses!$C:$C,$B37,Expenses!$D:$D,$C37,Expenses!$E:$E,$D37,Expenses!$J:$J,"Paid"))) | H37: =IF($A37="","",IF($C37="",SUMIFS(Expenses!$H:$H,Expenses!$C:$C,$B37,Expenses!$E:$E,$D37,Expenses!$J:$J,"Committed"),SUMIFS(Expenses!$H:$H,Expenses!$C:$C,$B37,Expenses!$D:$D,$C37,Expenses!$E:$E,$D37,Expenses!$J:$J,"Committed"))) | I37: =IF($A37="","",$F37-$G37-$H37) | J37: =IF($A37="","",$F37-($G37+$H37)) | K37: =IF(OR($A37="",$F37=0),"",($G37+$H37-$F37)/$F37) | L37: =IF($A37="","",IF($F37=0,"",IF(($G37+$H37)>$F37*(1+OverrunAlert),"Over",IF(($G37+$H37)>$F37,"Watch",IF(($G37+$H37)<$F37*0.85,"Under","On Track")))))
A38: BL-034 | B38: PRJ-002 | C38: RM-09 | D38: Materials | E38: Cabin bath package | F38: 9200 | G38: =IF($A38="","",IF($C38="",SUMIFS(Expenses!$H:$H,Expenses!$C:$C,$B38,Expenses!$E:$E,$D38,Expenses!$J:$J,"Paid"),SUMIFS(Expenses!$H:$H,Expenses!$C:$C,$B38,Expenses!$D:$D,$C38,Expenses!$E:$E,$D38,Expenses!$J:$J,"Paid"))) | H38: =IF($A38="","",IF($C38="",SUMIFS(Expenses!$H:$H,Expenses!$C:$C,$B38,Expenses!$E:$E,$D38,Expenses!$J:$J,"Committed"),SUMIFS(Expenses!$H:$H,Expenses!$C:$C,$B38,Expenses!$D:$D,$C38,Expenses!$E:$E,$D38,Expenses!$J:$J,"Committed"))) | I38: =IF($A38="","",$F38-$G38-$H38) | J38: =IF($A38="","",$F38-($G38+$H38)) | K38: =IF(OR($A38="",$F38=0),"",($G38+$H38-$F38)/$F38) | L38: =IF($A38="","",IF($F38=0,"",IF(($G38+$H38)>$F38*(1+OverrunAlert),"Over",IF(($G38+$H38)>$F38,"Watch",IF(($G38+$H38)<$F38*0.85,"Under","On Track")))))
A39: BL-035 | B39: PRJ-002 | C39: RM-09 | D39: Labor | E39: Gut and reset | F39: 6800 | G39: =IF($A39="","",IF($C39="",SUMIFS(Expenses!$H:$H,Expenses!$C:$C,$B39,Expenses!$E:$E,$D39,Expenses!$J:$J,"Paid"),SUMIFS(Expenses!$H:$H,Expenses!$C:$C,$B39,Expenses!$D:$D,$C39,Expenses!$E:$E,$D39,Expenses!$J:$J,"Paid"))) | H39: =IF($A39="","",IF($C39="",SUMIFS(Expenses!$H:$H,Expenses!$C:$C,$B39,Expenses!$E:$E,$D39,Expenses!$J:$J,"Committed"),SUMIFS(Expenses!$H:$H,Expenses!$C:$C,$B39,Expenses!$D:$D,$C39,Expenses!$E:$E,$D39,Expenses!$J:$J,"Committed"))) | I39: =IF($A39="","",$F39-$G39-$H39) | J39: =IF($A39="","",$F39-($G39+$H39)) | K39: =IF(OR($A39="",$F39=0),"",($G39+$H39-$F39)/$F39) | L39: =IF($A39="","",IF($F39=0,"",IF(($G39+$H39)>$F39*(1+OverrunAlert),"Over",IF(($G39+$H39)>$F39,"Watch",IF(($G39+$H39)<$F39*0.85,"Under","On Track")))))
A40: BL-036 | B40: PRJ-002 | D40: Design | E40: Concept + drawings | F40: 1200 | G40: =IF($A40="","",IF($C40="",SUMIFS(Expenses!$H:$H,Expenses!$C:$C,$B40,Expenses!$E:$E,$D40,Expenses!$J:$J,"Paid"),SUMIFS(Expenses!$H:$H,Expenses!$C:$C,$B40,Expenses!$D:$D,$C40,Expenses!$E:$E,$D40,Expenses!$J:$J,"Paid"))) | H40: =IF($A40="","",IF($C40="",SUMIFS(Expenses!$H:$H,Expenses!$C:$C,$B40,Expenses!$E:$E,$D40,Expenses!$J:$J,"Committed"),SUMIFS(Expenses!$H:$H,Expenses!$C:$C,$B40,Expenses!$D:$D,$C40,Expenses!$E:$E,$D40,Expenses!$J:$J,"Committed"))) | I40: =IF($A40="","",$F40-$G40-$H40) | J40: =IF($A40="","",$F40-($G40+$H40)) | K40: =IF(OR($A40="",$F40=0),"",($G40+$H40-$F40)/$F40) | L40: =IF($A40="","",IF($F40=0,"",IF(($G40+$H40)>$F40*(1+OverrunAlert),"Over",IF(($G40+$H40)>$F40,"Watch",IF(($G40+$H40)<$F40*0.85,"Under","On Track")))))
A41: BL-037 | B41: PRJ-002 | D41: Contingency | E41: 10% reserve | F41: 1300 | G41: =IF($A41="","",IF($C41="",SUMIFS(Expenses!$H:$H,Expenses!$C:$C,$B41,Expenses!$E:$E,$D41,Expenses!$J:$J,"Paid"),SUMIFS(Expenses!$H:$H,Expenses!$C:$C,$B41,Expenses!$D:$D,$C41,Expenses!$E:$E,$D41,Expenses!$J:$J,"Paid"))) | H41: =IF($A41="","",IF($C41="",SUMIFS(Expenses!$H:$H,Expenses!$C:$C,$B41,Expenses!$E:$E,$D41,Expenses!$J:$J,"Committed"),SUMIFS(Expenses!$H:$H,Expenses!$C:$C,$B41,Expenses!$D:$D,$C41,Expenses!$E:$E,$D41,Expenses!$J:$J,"Committed"))) | I41: =IF($A41="","",$F41-$G41-$H41) | J41: =IF($A41="","",$F41-($G41+$H41)) | K41: =IF(OR($A41="",$F41=0),"",($G41+$H41-$F41)/$F41) | L41: =IF($A41="","",IF($F41=0,"",IF(($G41+$H41)>$F41*(1+OverrunAlert),"Over",IF(($G41+$H41)>$F41,"Watch",IF(($G41+$H41)<$F41*0.85,"Under","On Track")))))
E43: TOTAL (all lines) | F43: =SUM(F5:F41) | G43: =SUM(G5:G41) | H43: =SUM(H5:H41) | I43: =SUM(I5:I41) | J43: =F43-G43-H43

Sheet Expenses
A1: EXPENSES
A2: Every dollar · Planned / Committed / Paid · add rows below, keep Status valid
A4: Expense ID | B4: Date | C4: Project ID | D4: Room ID | E4: Category | F4: Vendor | G4: Description | H4: Amount | I4: Method | J4: Status | K4: Receipt / Invoice | L4: Approved By
A5: EXP-001 | B5: 46089 | C5: PRJ-001 | E5: Design | F5: Luna Interiors | G5: Design retainer | H5: 2400 | I5: ACH | J5: Paid | K5: INV-LUNA-110 | L5: Alex Rivera
A6: EXP-002 | B6: 46114 | C6: PRJ-001 | E6: Permits | F6: City of Portland | G6: Building permit | H6: 840 | I6: Credit Card | J6: Paid | K6: PMT-2026-441 | L6: Marcus Webb
A7: EXP-003 | B7: 46130 | C7: PRJ-001 | E7: Permits | F7: City of Portland | G7: Electrical + plumbing permits | H7: 610 | I7: Credit Card | J7: Paid | K7: PMT-2026-478 | L7: Marcus Webb
A8: EXP-004 | B8: 46146 | C8: PRJ-001 | E8: Design | F8: Luna Interiors | G8: Drawings + 3D package | H8: 1800 | I8: ACH | J8: Paid | K8: INV-LUNA-126 | L8: Alex Rivera
A9: EXP-005 | B9: 46164 | C9: PRJ-001 | E9: Labor | F9: Ironwood Construction | G9: Demolition + dumpsters | H9: 2800 | I9: Check | J9: Paid | K9: INV-IW-204 | L9: Alex Rivera
A10: EXP-006 | B10: 46179 | C10: PRJ-001 | D10: RM-01 | E10: Labor | F10: Northwest Electric | G10: Kitchen / bath rough-in | H10: 1900 | I10: ACH | J10: Paid | K10: INV-NWE-88 | L10: Marcus Webb
A11: EXP-007 | B11: 46185 | C11: PRJ-001 | D11: RM-03 | E11: Labor | F11: Pacific Plumbing | G11: Bath / laundry rough-in | H11: 2400 | I11: ACH | J11: Paid | K11: INV-PP-301 | L11: Marcus Webb
A12: EXP-008 | B12: 46193 | C12: PRJ-001 | D12: RM-03 | E12: Materials | F12: Tile & Timber Co. | G12: Porcelain floor + wall tile | H12: 3180 | I12: Credit Card | J12: Paid | K12: PO-114 | L12: Sofia Alvarez
A13: EXP-009 | B13: 46201 | C13: PRJ-001 | D13: RM-03 | E13: Materials | F13: Ferguson | G13: Bath fixtures package | H13: 2140 | I13: Credit Card | J13: Paid | K13: FERG-9921 | L13: Sofia Alvarez
A14: EXP-010 | B14: 46205 | C14: PRJ-001 | D14: RM-03 | E14: Materials | F14: WarmFloor Co. | G14: Heated floor kit | H14: 1680 | I14: Credit Card | J14: Paid | K14: WF-441 | L14: Marcus Webb
A15: EXP-011 | B15: 46211 | C15: PRJ-001 | D15: RM-01 | E15: Labor | F15: Pacific Plumbing | G15: Kitchen sink relocate | H15: 1280 | I15: ACH | J15: Paid | K15: INV-PP-318 | L15: Marcus Webb
A16: EXP-012 | B16: 46218 | C16: PRJ-001 | D16: RM-03 | E16: Labor | F16: Heritage Tile & Stone | G16: Primary bath tile labor (50%) | H16: 2100 | I16: ACH | J16: Paid | K16: INV-HT-77 | L16: Marcus Webb
A17: EXP-013 | B17: 46221 | C17: PRJ-001 | D17: RM-07 | E17: Materials | F17: Tile & Timber Co. | G17: Laundry tile + sink | H17: 860 | I17: Credit Card | J17: Paid | K17: PO-129 | L17: Sofia Alvarez
A18: EXP-014 | B18: 46225 | C18: PRJ-001 | D18: RM-07 | E18: Labor | F18: Pacific Plumbing | G18: Laundry install | H18: 980 | I18: ACH | J18: Paid | K18: INV-PP-330 | L18: Marcus Webb
A19: EXP-015 | B19: 46231 | C19: PRJ-001 | D19: RM-01 | E19: Materials | F19: Timberline Floors | G19: White oak 7in — kitchen/living/dining | H19: 6400 | I19: ACH | J19: Paid | K19: PO-140 | L19: Sofia Alvarez
A20: EXP-016 | B20: 46236 | C20: PRJ-001 | D20: RM-01 | E20: Materials | F20: Cascade Cabinets | G20: Cabinet deposit 50% | H20: 7400 | I20: Wire | J20: Paid | K20: INV-CC-501 | L20: Alex Rivera
A21: EXP-017 | B21: 46239 | C21: PRJ-001 | D21: RM-02 | E21: Labor | F21: Timberline Floors | G21: Floor install progress | H21: 1800 | I21: ACH | J21: Paid | K21: INV-TF-19 | L21: Marcus Webb
... A23: EXP-019 | B23: 46244 | C23: PRJ-001 | D23: RM-03 | E23: Labor | F23: Pacific Plumbing | G23: Bath trim-out | H23: 1460 | I23: ACH | J23: Paid | K23: INV-PP-341 | L23: Marcus Webb
A24: EXP-020 | B24: 46246 | C24: PRJ-001 | E24: Inspections | F24: City of Portland | G24: Plumbing + electrical inspection | H24: 240 | I24: Credit Card | J24: Paid | K24: INSP-0812 | L24: Marcus Webb
A25: EXP-021 | B25: 46248 | C25: PRJ-001 | D25: RM-01 | E25: Materials | F25: Sub-Zero / Wolf dealer | G25: Range + fridge deposit | H25: 2700 | I25: Credit Card | J25: Paid | K25: APPL-01 | L25: Alex Rivera
A26: EXP-022 | B26: 46250 | C26: PRJ-001 | D26: RM-01 | E26: Materials | F26: Caesarstone | G26: Perimeter quartz | H26: 2480 | I26: Credit Card | J26: Paid | K26: CS-882 | L26: Sofia Alvarez
A27: EXP-023 | B27: 46252 | C27: PRJ-001 | E27: Labor | F27: Ironwood Construction | G27: August PM / supervision | H27: 1550 | I27: ACH | J27: Paid | K27: INV-IW-228 | L27: Alex Rivera
A28: EXP-024 | B28: 46254 | C28: PRJ-001 | D28: RM-01 | E28: Delivery | F28: Cascade Cabinets | G28: Cabinet freight | H28: 420 | I28: Credit Card | J28: Paid | K28: FRT-88 | L28: Maya Chen
A29: EXP-025 | B29: 46256 | C29: PRJ-001 | D29: RM-05 | E29: Materials | F29: BrightPath Lighting | G29: Dining sconces | H29: 380 | I29: Credit Card | J29: Paid | K29: BP-204 | L29: Sofia Alvarez
A30: EXP-026 | B30: 46259 | C30: PRJ-001 | D30: RM-01 | E30: Materials | F30: Cascade Cabinets | G30: Cabinet balance | H30: 7400 | I30: Wire | J30: Committed | K30: INV-CC-502 | L30: Alex Rivera
A31: EXP-027 | B31: 46262 | C31: PRJ-001 | D31: RM-01 | E31: Labor | F31: Cascade Cabinets | G31: Install labor | H31: 3600 | I31: ACH | J31: Committed | K31: INV-CC-510 | L31: Marcus Webb
A32: EXP-028 | B32: 46269 | C32: PRJ-001 | D32: RM-01 | E32: Materials | F32: Heritage Tile & Stone | G32: Island porcelain slab | H32: 1860 | I32: Credit Card | J32: Committed | K32: PO-155 | L32: Sofia Alvarez
A33: EXP-029 | B33: 46273 | C33: PRJ-001 | D33: RM-01 | E33: Materials | F33: BrightPath Lighting | G33: Island pendants | H33: 890 | I33: Credit Card | J33: Planned | K33: BP-220 | L33: Sofia Alvarez
A34: EXP-030 | B34: 46277 | C34: PRJ-001 | D34: RM-04 | E34: Materials | F34: Sherwin-Williams | G34: Guest bedroom paint | H34: 240 | I34: Credit Card | J34: Planned
A35: EXP-031 | B35: 46283 | C35: PRJ-001 | D35: RM-02 | E35: Furniture | F35: Article | G35: Sofa + coffee table | H35: 3400 | I35: Credit Card | J35: Planned | L35: Sofia Alvarez
A36: EXP-032 | B36: 46297 | C36: PRJ-001 | D36: RM-06 | E36: Materials | F36: Garden & Gate | G36: Path stone deposit | H36: 1200 | I36: Check | J36: Planned
A37: EXP-033 | B37: 46235 | C37: PRJ-002 | E37: Design | F37: Luna Interiors | G37: Cabin bath concept | H37: 600 | I37: ACH | J37: Paid | K37: INV-LUNA-140 | L37: Alex Rivera
A38: EXP-034 | B38: 46233 | C38: PRJ-001 | D38: RM-01 | E38: Labor | F38: Northwest Electric | G38: Finish electrical progress | H38: 720 | I38: ACH | J38: Paid | K38: INV-NWE-97 | L38: Marcus Webb
A39: EXP-035 | B39: 46253 | C39: PRJ-001 | D39: RM-08 | E39: Materials | F39: Rejuvenation | G39: Hook rail + hooks | H39: 186 | I39: Credit Card | J39: Paid | K39: REJ-33 | L39: Alex Rivera

Sheet Finance
A1: FINANCE
A2: Financial dashboard · planned vs actual, by room, by category, by month
A5: BUDGET (active project) | D5: SPENT | G5: COMMITTED | J5: REMAINING
A6: =IFERROR(SUMIF(Projects!A:A,ActiveProject,Projects!J:J),0) | D6: =IFERROR(SUMIFS(Expenses!H:H,Expenses!C:C,ActiveProject,Expenses!J:J,"Paid"),0) | G6: =IFERROR(SUMIFS(Expenses!H:H,Expenses!C:C,ActiveProject,Expenses!J:J,"Committed"),0) | J6: =A6-D6-G6
A7: Total planned | D7: Paid to date | G7: Approved, not yet paid | J7: Budget − spent − committed
A9: % USED | D9: CONTINGENCY LEFT | G9: THIS MONTH SPENT | J9: HEALTH
A10: =IFERROR((D6+G6)/A6,0) | D10: =IFERROR(SUMIFS(Budget!I:I,Budget!B:B,ActiveProject,Budget!D:D,"Contingency"),0) | G10: =SUMIFS(Expenses!H:H,Expenses!C:C,ActiveProject,Expenses!J:J,"Paid",Expenses!B:B,">="&DATE(YEAR(AsOfDate),MONTH(AsOfDate),1),Expenses!B:B,"<"&DATE(YEAR(AsOfDate),MONTH(AsOfDate)+1,1)) | J10: =IF((D6+G6)>A6*(1+OverrunAlert),"OVER",IF((D6+G6)>A6,"WATCH","ON TRACK"))
A11: Spent + committed | D11: Watch the 10% floor | G11: Paid in current month | J11: Vs overrun threshold
A13: Cost by category | H13: Cost by room (active project)
A14: Category | B14: Planned | C14: Spent | D14: Committed | E14: Remaining | F14: % Used | H14: Room | I14: Budget | J14: Spent | K14: Committed | L14: Remaining | M14: % Used
A15: Labor | B15: =SUMIFS(Budget!F:F,Budget!B:B,ActiveProject,Budget!D:D,A15) | C15: =SUMIFS(Expenses!H:H,Expenses!C:C,ActiveProject,Expenses!E:E,A15,Expenses!J:J,"Paid") | D15: =SUMIFS(Expenses!H:H,Expenses!C:C,ActiveProject,Expenses!E:E,A15,Expenses!J:J,"Committed") | E15: =B15-C15-D15 | F15: =IF(B15=0,"",(C15+D15)/B15) | H15: Kitchen | I15: =SUMIF(Rooms!A:A,"RM-01",Rooms!K:K) | J15: =SUMIFS(Expenses!H:H,Expenses!D:D,"RM-01",Expenses!J:J,"Paid") | K15: =SUMIFS(Expenses!H:H,Expenses!D:D,"RM-01",Expenses!J:J,"Committed") | L15: =I15-J15-K15 | M15: =IF(I15=0,"",(J15+K15)/I15)
A16: Materials | B16: =SUMIFS(Budget!F:F,Budget!B:B,ActiveProject,Budget!D:D,A16) | C16: =SUMIFS(Expenses!H:H,Expenses!C:C,ActiveProject,Expenses!E:E,A16,Expenses!J:J,"Paid") | D16: =SUMIFS(Expenses!H:H,Expenses!C:C,ActiveProject,Expenses!E:E,A16,Expenses!J:J,"Committed") | E16: =B16-C16-D16 | F16: =IF(B16=0,"",(C16+D16)/B16) | H16: Living Room | I16: =SUMIF(Rooms!A:A,"RM-02",Rooms!K:K) | J16: =SUMIFS(Expenses!H:H,Expenses!D:D,"RM-02",Expenses!J:J,"Paid") | K16: =SUMIFS(Expenses!H:H,Expenses!D:D,"RM-02",Expenses!J:J,"Committed") | L16: =I16-J16-K16 | M16: =IF(I16=0,"",(J16+K16)/I16)
A17: Design | B17: =SUMIFS(Budget!F:F,Budget!B:B,ActiveProject,Budget!D:D,A17) | C17: =SUMIFS(Expenses!H:H,Expenses!C:C,ActiveProject,Expenses!E:E,A17,Expenses!J:J,"Paid") | D17: =SUMIFS(Expenses!H:H,Expenses!C:C,ActiveProject,Expenses!E:E,A17,Expenses!J:J,"Committed") | E17: =B17-C17-D17 | F17: =IF(B17=0,"",(C17+D17)/B17) | H17: Primary Bathroom | I17: =SUMIF(Rooms!A:A,"RM-03",Rooms!K:K) | J17: =SUMIFS(Expenses!H:H,Expenses!D:D,"RM-03",Expenses!J:J,"Paid") | K17: =SUMIFS(Expenses!H:H,Expenses!D:D,"RM-03",Expenses!J:J,"Committed") | L17: =I17-J17-K17 | M17: =IF(I17=0,"",(J17+K17)/I17)
A18: Permits | B18: =SUMIFS(Budget!F:F,Budget!B:B,ActiveProject,Budget!D:D,A18) | C18: =SUMIFS(Expenses!H:H,Expenses!C:C,ActiveProject,Expenses!E:E,A18,Expenses!J:J,"Paid") | D18: =SUMIFS(Expenses!H:H,Expenses!C:C,ActiveProject,Expenses!E:E,A18,Expenses!J:J,"Committed") | E18: =B18-C18-D18 | F18: =IF(B18=0,"",(C18+D18)/B18) | H18: Guest Bedroom | I18: =SUMIF(Rooms!A:A,"RM-04",Rooms!K:K) | J18: =SUMIFS(Expenses!H:H,Expenses!D:D,"RM-04",Expenses!J:J,"Paid") | K18: =SUMIFS(Expenses!H:H,Expenses!D:D,"RM-04",Expenses!J:J,"Committed") | L18: =I18-J18-K18 | M18: =IF(I18=0,"",(J18+K18)/I18)
A19: Delivery | B19: =SUMIFS(Budget!F:F,Budget!B:B,ActiveProject,Budget!D:D,A19) | C19: =SUMIFS(Expenses!H:H,Expenses!C:C,ActiveProject,Expenses!E:E,A19,Expenses!J:J,"Paid") | D19: =SUMIFS(Expenses!H:H,Expenses!C:C,ActiveProject,Expenses!E:E,A19,Expenses!J:J,"Committed") | E19: =B19-C19-D19 | F19: =IF(B19=0,"",(C19+D19)/B19) | H19: Dining Room | I19: =SUMIF(Rooms!A:A,"RM-05",Rooms!K:K) | J19: =SUMIFS(Expenses!H:H,Expenses!D:D,"RM-05",Expenses!J:J,"Paid") | K19: =SUMIFS(Expenses!H:H,Expenses!D:D,"RM-05",Expenses!J:J,"Committed") | L19: =I19-J19-K19 | M19: =IF(I19=0,"",(J19+K19)/I19)
A20: Contingency | B20: =SUMIFS(Budget!F:F,Budget!B:B,ActiveProject,Budget!D:D,A20) | C20: =SUMIFS(Expenses!H:H,Expenses!C:C,ActiveProject,Expenses!E:E,A20,Expenses!J:J,"Paid") | D20: =SUMIFS(Expenses!H:H,Expenses!C:C,ActiveProject,Expenses!E:E,A20,Expenses!J:J,"Committed") | E20: =B20-C20-D20 | F20: =IF(B20=0,"",(C20+D20)/B20) | H20: Exterior / Garden | I20: =SUMIF(Rooms!A:A,"RM-06",Rooms!K:K) | J20: =SUMIFS(Expenses!H:H,Expenses!D:D,"RM-06",Expenses!J:J,"Paid") | K20: =SUMIFS(Expenses!H:H,Expenses!D:D,"RM-06",Expenses!J:J,"Committed") | L20: =I20-J20-K20 | M20: =IF(I20=0,"",(J20+K20)/I20)
A21: Appliances | B21: =SUMIFS(Budget!F:F,Budget!B:B,ActiveProject,Budget!D:D,A21) | C21: =SUMIFS(Expenses!H:H,Expenses!C:C,ActiveProject,Expenses!E:E,A21,Expenses!J:J,"Paid") | D21: =SUMIFS(Expenses!H:H,Expenses!C:C,ActiveProject,Expenses!E:E,A21,Expenses!J:J,"Committed") | E21: =B21-C21-D21 | F21: =IF(B21=0,"",(C21+D21)/B21) | H21: Laundry | I21: =SUMIF(Rooms!A:A,"RM-07",Rooms!K:K) | J21: =SUMIFS(Expenses!H:H,Expenses!D:D,"RM-07",Expenses!J:J,"Paid") | K21: =SUMIFS(Expenses!H:H,Expenses!D:D,"RM-07",Expenses!J:J,"Committed") | L21: =I21-J21-K21 | M21: =IF(I21=0,"",(J21+K21)/I21)
A22: Furniture | B22: =SUMIFS(Budget!F:F,Budget!B:B,ActiveProject,Budget!D:D,A22) | C22: =SUMIFS(Expenses!H:H,Expenses!C:C,ActiveProject,Expenses!E:E,A22,Expenses!J:J,"Paid") | D22: =SUMIFS(Expenses!H:H,Expenses!C:C,ActiveProject,Expenses!E:E,A22,Expenses!J:J,"Committed") | E22: =B22-C22-D22 | F22: =IF(B22=0,"",(C22+D22)/B22) | H22: Entry / Foyer | I22: =SUMIF(Rooms!A:A,"RM-08",Rooms!K:K) | J22: =SUMIFS(Expenses!H:H,Expenses!D:D,"RM-08",Expenses!J:J,"Paid") | K22: =SUMIFS(Expenses!H:H,Expenses!D:D,"RM-08",Expenses!J:J,"Committed") | L22: =I22-J22-K22 | M22: =IF(I22=0,"",(J22+K22)/I22)
A23: Inspections | B23: =SUMIFS(Budget!F:F,Budget!B:B,ActiveProject,Budget!D:D,A23) | C23: =SUMIFS(Expenses!H:H,Expenses!C:C,ActiveProject,Expenses!E:E,A23,Expenses!J:J,"Paid") | D23: =SUMIFS(Expenses!H:H,Expenses!C:C,ActiveProject,Expenses!E:E,A23,Expenses!J:J,"Committed") | E23: =B23-C23-D23 | F23: =IF(B23=0,"",(C23+D23)/B23) | H23: =IFERROR(INDEX(Rooms!$C:$C,SMALL(IF(Rooms!$B$5:$B$80=ActiveProject,ROW(Rooms!$B$5:$B$80)),9)),"")
A24: Other | B24: =SUMIFS(Budget!F:F,Budget!B:B,ActiveProject,Budget!D:D,A24) | C24: =SUMIFS(Expenses!H:H,Expenses!C:C,ActiveProject,Expenses!E:E,A24,Expenses!J:J,"Paid") | D24: =SUMIFS(Expenses!H:H,Expenses!C:C,ActiveProject,Expenses!E:E,A24,Expenses!J:J,"Committed") | E24: =B24-C24-D24 | F24: =IF(B24=0,"",(C24+D24)/B24) | H24: =IFERROR(INDEX(Rooms!$C:$C,SMALL(IF(Rooms!$B$5:$B$80=ActiveProject,ROW(Rooms!$B$5:$B$80)),10)),"")
H25: =IFERROR(INDEX(Rooms!$C:$C,SMALL(IF(Rooms!$B$5:$B$80=ActiveProject,ROW(Rooms!$B$5:$B$80)),11)),"")
H26: =IFERROR(INDEX(Rooms!$C:$C,SMALL(IF(Rooms!$B$5:$B$80=ActiveProject,ROW(Rooms!$B$5:$B$80)),12)),"")
A27: Monthly spending (paid)
A28: Month | B28: Spent | C28: Committed dated | H28: Smart alerts
A29: Mar 2026 | B29: =SUMIFS(Expenses!H:H,Expenses!C:C,ActiveProject,Expenses!J:J,"Paid",Expenses!B:B,">="&DATE(2026,3,1),Expenses!B:B,"<"&DATE(2026,4,1)) | C29: =SUMIFS(Expenses!H:H,Expenses!C:C,ActiveProject,Expenses!J:J,"Committed",Expenses!B:B,">="&DATE(2026,3,1),Expenses!B:B,"<"&DATE(2026,4,1)) | H29: =IF((D6+G6)>A6,"🔴 Project is over planned budget","🟢 Project within planned budget")
A30: Apr 2026 | B30: =SUMIFS(Expenses!H:H,Expenses!C:C,ActiveProject,Expenses!J:J,"Paid",Expenses!B:B,">="&DATE(2026,4,1),Expenses!B:B,"<"&DATE(2026,5,1)) | C30: =SUMIFS(Expenses!H:H,Expenses!C:C,ActiveProject,Expenses!J:J,"Committed",Expenses!B:B,">="&DATE(2026,4,1),Expenses!B:B,"<"&DATE(2026,5,1)) | H30: =IF(D10<A6*ContingencyFloor,"🔴 Contingency has fallen below the threshold","🟢 Contingency healthy")
